2021-11-17 17:59:19,215 - util.py[DEBUG]: Cloud-init v. 21.3-1-g6803368d-0ubuntu1~20.04.4 running 'init-local' at Wed, 17 Nov 2021 17:59:19 +0000. Up 9.93 seconds.
2021-11-17 17:59:19,216 - main.py[DEBUG]: No kernel command line url found.
2021-11-17 17:59:19,216 - main.py[DEBUG]: Closing stdin.
2021-11-17 17:59:19,220 - util.py[DEBUG]: Writing to /var/log/cloud-init.log - ab: [644] 0 bytes
2021-11-17 17:59:19,221 - util.py[DEBUG]: Changing the ownership of /var/log/cloud-init.log to 104:4
2021-11-17 17:59:19,221 - util.py[DEBUG]: Writing to /var/lib/cloud/data/python-version - wb: [644] 3 bytes
2021-11-17 17:59:19,222 - util.py[DEBUG]: Attempting to remove /var/lib/cloud/instance/boot-finished
2021-11-17 17:59:19,223 - util.py[DEBUG]: Attempting to remove /var/lib/cloud/data/no-net
2021-11-17 17:59:19,223 - handlers.py[DEBUG]: start: init-local/check-cache: attempting to read from cache [check]
2021-11-17 17:59:19,224 - util.py[DEBUG]: Reading from /var/lib/cloud/instance/obj.pkl (quiet=False)
2021-11-17 17:59:19,224 - stages.py[DEBUG]: no cache found
2021-11-17 17:59:19,224 - handlers.py[DEBUG]: finish: init-local/check-cache: SUCCESS: no cache found
2021-11-17 17:59:19,224 - util.py[DEBUG]: Attempting to remove /var/lib/cloud/instance
2021-11-17 17:59:19,331 - stages.py[DEBUG]: Using distro class <class 'cloudinit.distros.ubuntu.Distro'>
2021-11-17 17:59:19,331 - __init__.py[DEBUG]: Looking for data source in: ['NoCloud', 'None'], via packages ['', 'cloudinit.sources'] that matches dependencies ['FILESYSTEM']
2021-11-17 17:59:19,356 - __init__.py[DEBUG]: Searching for local data source in: ['DataSourceNoCloud']
2021-11-17 17:59:19,356 - handlers.py[DEBUG]: start: init-local/search-NoCloud: searching for local data from DataSourceNoCloud
2021-11-17 17:59:19,356 - __init__.py[DEBUG]: Seeing if we can get any data from <class 'cloudinit.sources.DataSourceNoCloud.DataSourceNoCloud'>
2021-11-17 17:59:19,357 - __init__.py[DEBUG]: Update datasource metadata and network config due to events: boot-new-instance
2021-11-17 17:59:19,357 - dmi.py[DEBUG]: querying dmi data /sys/class/dmi/id/product_serial
2021-11-17 17:59:19,357 - util.py[DEBUG]: Reading from /var/lib/cloud/seed/nocloud/user-data (quiet=False)
2021-11-17 17:59:19,357 - util.py[DEBUG]: Reading from /var/lib/cloud/seed/nocloud/meta-data (quiet=False)
2021-11-17 17:59:19,357 - util.py[DEBUG]: Reading from /var/lib/cloud/seed/nocloud/vendor-data (quiet=False)
2021-11-17 17:59:19,357 - util.py[DEBUG]: Reading from /var/lib/cloud/seed/nocloud/network-config (quiet=False)
2021-11-17 17:59:19,357 - util.py[DEBUG]: Reading from /var/lib/cloud/seed/nocloud-net/user-data (quiet=False)
2021-11-17 17:59:19,357 - util.py[DEBUG]: Reading from /var/lib/cloud/seed/nocloud-net/meta-data (quiet=False)
2021-11-17 17:59:19,357 - util.py[DEBUG]: Reading from /var/lib/cloud/seed/nocloud-net/vendor-data (quiet=False)
2021-11-17 17:59:19,357 - util.py[DEBUG]: Reading from /var/lib/cloud/seed/nocloud-net/network-config (quiet=False)
2021-11-17 17:59:19,358 - subp.py[DEBUG]: Running command ['blkid', '-tTYPE=vfat', '-odevice'] with allowed return codes [0, 2] (shell=False, capture=True)
2021-11-17 17:59:19,413 - subp.py[DEBUG]: Running command ['blkid', '-tTYPE=iso9660', '-odevice'] with allowed return codes [0, 2] (shell=False, capture=True)
2021-11-17 17:59:19,422 - subp.py[DEBUG]: Running command ['blkid', '-tLABEL=CIDATA', '-odevice'] with allowed return codes [0, 2] (shell=False, capture=True)
2021-11-17 17:59:19,445 - subp.py[DEBUG]: Running command ['blkid', '-tLABEL=cidata', '-odevice'] with allowed return codes [0, 2] (shell=False, capture=True)
2021-11-17 17:59:19,457 - subp.py[DEBUG]: Running command ['blkid', '-tLABEL_FATBOOT=cidata', '-odevice'] with allowed return codes [0, 2] (shell=False, capture=True)
2021-11-17 17:59:19,473 - DataSourceNoCloud.py[DEBUG]: Attempting to use data from /dev/sr0
2021-11-17 17:59:19,473 - util.py[DEBUG]: Reading from /proc/mounts (quiet=False)
2021-11-17 17:59:19,473 - util.py[DEBUG]: Read 2697 bytes from /proc/mounts
2021-11-17 17:59:19,473 - util.py[DEBUG]: Fetched {'sysfs': {'fstype': 'sysfs', 'mountpoint': '/sys', 'opts': 'rw,nosuid,nodev,noexec,relatime'}, 'proc': {'fstype': 'proc', 'mountpoint': '/proc', 'opts': 'rw,nosuid,nodev,noexec,relatime'}, 'udev': {'fstype': 'devtmpfs', 'mountpoint': '/dev', 'opts': 'rw,nosuid,noexec,relatime,size=485108k,nr_inodes=121277,mode=755'}, 'devpts': {'fstype': 'devpts', 'mountpoint': '/dev/pts', 'opts': 'rw,nosuid,noexec,relatime,gid=5,mode=620,ptmxmode=000'}, 'tmpfs': {'fstype': 'tmpfs', 'mountpoint': '/sys/fs/cgroup', 'opts': 'ro,nosuid,nodev,noexec,mode=755'}, '/dev/vda1': {'fstype': 'ext4', 'mountpoint': '/', 'opts': 'rw,relatime'}, 'securityfs': {'fstype': 'securityfs', 'mountpoint': '/sys/kernel/security', 'opts': 'rw,nosuid,nodev,noexec,relatime'}, 'cgroup2': {'fstype': 'cgroup2', 'mountpoint': '/sys/fs/cgroup/unified', 'opts': 'rw,nosuid,nodev,noexec,relatime,nsdelegate'}, 'cgroup': {'fstype': 'cgroup', 'mountpoint': '/sys/fs/cgroup/freezer', 'opts': 'rw,nosuid,nodev,noexec,relatime,freezer'}, 'pstore': {'fstype': 'pstore', 'mountpoint': '/sys/fs/pstore', 'opts': 'rw,nosuid,nodev,noexec,relatime'}, 'none': {'fstype': 'bpf', 'mountpoint': '/sys/fs/bpf', 'opts': 'rw,nosuid,nodev,noexec,relatime,mode=700'}, 'systemd-1': {'fstype': 'autofs', 'mountpoint': '/proc/sys/fs/binfmt_misc', 'opts': 'rw,relatime,fd=28,pgrp=1,timeout=0,minproto=5,maxproto=5,direct,pipe_ino=13395'}, 'hugetlbfs': {'fstype': 'hugetlbfs', 'mountpoint': '/dev/hugepages', 'opts': 'rw,relatime,pagesize=2M'}, 'mqueue': {'fstype': 'mqueue', 'mountpoint': '/dev/mqueue', 'opts': 'rw,nosuid,nodev,noexec,relatime'}, 'debugfs': {'fstype': 'debugfs', 'mountpoint': '/sys/kernel/debug', 'opts': 'rw,nosuid,nodev,noexec,relatime'}, 'tracefs': {'fstype': 'tracefs', 'mountpoint': '/sys/kernel/tracing', 'opts': 'rw,nosuid,nodev,noexec,relatime'}, 'fusectl': {'fstype': 'fusectl', 'mountpoint': '/sys/fs/fuse/connections', 'opts': 'rw,nosuid,nodev,noexec,relatime'}, 'configfs': {'fstype': 'configfs', 'mountpoint': '/sys/kernel/config', 'opts': 'rw,nosuid,nodev,noexec,relatime'}, '/dev/loop1': {'fstype': 'squashfs', 'mountpoint': '/snap/lxd/21835', 'opts': 'ro,nodev,relatime'}, '/dev/loop0': {'fstype': 'squashfs', 'mountpoint': '/snap/core20/1169', 'opts': 'ro,nodev,relatime'}, '/dev/loop2': {'fstype': 'squashfs', 'mountpoint': '/snap/snapd/13640', 'opts': 'ro,nodev,relatime'}, '/dev/vda15': {'fstype': 'vfat', 'mountpoint': '/boot/efi', 'opts': 'rw,relatime,fmask=0077,dmask=0077,codepage=437,iocharset=iso8859-1,shortname=mixed,errors=remount-ro'}} mounts from proc
2021-11-17 17:59:19,474 - subp.py[DEBUG]: Running command ['mount', '-o', 'ro', '-t', 'auto', '/dev/sr0', '/run/cloud-init/tmp/tmpeaksmls2'] with allowed return codes [0] (shell=False, capture=True)
2021-11-17 17:59:19,556 - util.py[DEBUG]: Reading from /run/cloud-init/tmp/tmpeaksmls2//user-data (quiet=False)
2021-11-17 17:59:19,557 - util.py[DEBUG]: Read 1112 bytes from /run/cloud-init/tmp/tmpeaksmls2//user-data
2021-11-17 17:59:19,557 - util.py[DEBUG]: Reading from /run/cloud-init/tmp/tmpeaksmls2//meta-data (quiet=False)
2021-11-17 17:59:19,557 - util.py[DEBUG]: Read 56 bytes from /run/cloud-init/tmp/tmpeaksmls2//meta-data
2021-11-17 17:59:19,557 - util.py[DEBUG]: Reading from /run/cloud-init/tmp/tmpeaksmls2//vendor-data (quiet=False)
2021-11-17 17:59:19,558 - util.py[DEBUG]: Read 840 bytes from /run/cloud-init/tmp/tmpeaksmls2//vendor-data
2021-11-17 17:59:19,558 - util.py[DEBUG]: Reading from /run/cloud-init/tmp/tmpeaksmls2//network-config (quiet=False)
2021-11-17 17:59:19,558 - subp.py[DEBUG]: Running command ['umount', '/run/cloud-init/tmp/tmpeaksmls2'] with allowed return codes [0] (shell=False, capture=True)
2021-11-17 17:59:19,571 - util.py[DEBUG]: Attempting to load yaml from string of length 56 with allowed root types (<class 'dict'>,)
2021-11-17 17:59:19,572 - DataSourceNoCloud.py[DEBUG]: Using data from /dev/sr0
2021-11-17 17:59:19,573 - atomic_helper.py[DEBUG]: Atomically writing to file /run/cloud-init/instance-data-sensitive.json (via temporary file /run/cloud-init/tmp681gf_06) - w: [600] 4619 bytes/chars
2021-11-17 17:59:19,574 - atomic_helper.py[DEBUG]: Atomically writing to file /run/cloud-init/instance-data.json (via temporary file /run/cloud-init/tmplhlgfz1x) - w: [644] 1388 bytes/chars
2021-11-17 17:59:19,574 - handlers.py[DEBUG]: finish: init-local/search-NoCloud: SUCCESS: found local data from DataSourceNoCloud
2021-11-17 17:59:19,574 - stages.py[INFO]: Loaded datasource DataSourceNoCloud - DataSourceNoCloud [seed=/dev/sr0][dsmode=net]
2021-11-17 17:59:19,574 - util.py[DEBUG]: Reading from /etc/cloud/cloud.cfg (quiet=False)
2021-11-17 17:59:19,574 - util.py[DEBUG]: Read 3764 bytes from /etc/cloud/cloud.cfg
2021-11-17 17:59:19,575 - util.py[DEBUG]: Attempting to load yaml from string of length 3764 with allowed root types (<class 'dict'>,)
2021-11-17 17:59:19,615 - util.py[DEBUG]: Reading from /etc/cloud/cloud.cfg.d/90_dpkg.cfg (quiet=False)
2021-11-17 17:59:19,616 - util.py[DEBUG]: Read 309 bytes from /etc/cloud/cloud.cfg.d/90_dpkg.cfg
2021-11-17 17:59:19,616 - util.py[DEBUG]: Attempting to load yaml from string of length 309 with allowed root types (<class 'dict'>,)
2021-11-17 17:59:19,618 - util.py[DEBUG]: Reading from /etc/cloud/cloud.cfg.d/05_logging.cfg (quiet=False)
2021-11-17 17:59:19,618 - util.py[DEBUG]: Read 2070 bytes from /etc/cloud/cloud.cfg.d/05_logging.cfg
2021-11-17 17:59:19,618 - util.py[DEBUG]: Attempting to load yaml from string of length 2070 with allowed root types (<class 'dict'>,)
2021-11-17 17:59:19,621 - util.py[DEBUG]: Reading from /run/cloud-init/cloud.cfg (quiet=False)
2021-11-17 17:59:19,621 - util.py[DEBUG]: Read 35 bytes from /run/cloud-init/cloud.cfg
2021-11-17 17:59:19,621 - util.py[DEBUG]: Attempting to load yaml from string of length 35 with allowed root types (<class 'dict'>,)
2021-11-17 17:59:19,622 - util.py[DEBUG]: Attempting to load yaml from string of length 0 with allowed root types (<class 'dict'>,)
2021-11-17 17:59:19,622 - util.py[DEBUG]: loaded blob returned None, returning default.
2021-11-17 17:59:19,622 - util.py[DEBUG]: Attempting to remove /var/lib/cloud/instance
2021-11-17 17:59:19,622 - util.py[DEBUG]: Creating symbolic link from '/var/lib/cloud/instance' => '/var/lib/cloud/instances/test2'
2021-11-17 17:59:19,623 - util.py[DEBUG]: Reading from /var/lib/cloud/instances/test2/datasource (quiet=False)
2021-11-17 17:59:19,623 - util.py[DEBUG]: Writing to /var/lib/cloud/instances/test2/datasource - wb: [644] 65 bytes
2021-11-17 17:59:19,624 - util.py[DEBUG]: Writing to /var/lib/cloud/data/previous-datasource - wb: [644] 65 bytes
2021-11-17 17:59:19,624 - util.py[DEBUG]: Reading from /var/lib/cloud/data/instance-id (quiet=False)
2021-11-17 17:59:19,624 - stages.py[DEBUG]: previous iid found to be NO_PREVIOUS_INSTANCE_ID
2021-11-17 17:59:19,624 - util.py[DEBUG]: Writing to /var/lib/cloud/data/instance-id - wb: [644] 6 bytes
2021-11-17 17:59:19,625 - util.py[DEBUG]: Writing to /run/cloud-init/.instance-id - wb: [644] 6 bytes
2021-11-17 17:59:19,625 - util.py[DEBUG]: Writing to /var/lib/cloud/data/previous-instance-id - wb: [644] 24 bytes
2021-11-17 17:59:19,626 - util.py[DEBUG]: Writing to /var/lib/cloud/instance/obj.pkl - wb: [400] 7626 bytes
2021-11-17 17:59:19,626 - main.py[DEBUG]: [local] init will now be targeting instance id: test2. new=True
2021-11-17 17:59:19,626 - util.py[DEBUG]: Reading from /etc/cloud/cloud.cfg (quiet=False)
2021-11-17 17:59:19,626 - util.py[DEBUG]: Read 3764 bytes from /etc/cloud/cloud.cfg
2021-11-17 17:59:19,626 - util.py[DEBUG]: Attempting to load yaml from string of length 3764 with allowed root types (<class 'dict'>,)
2021-11-17 17:59:19,662 - util.py[DEBUG]: Reading from /etc/cloud/cloud.cfg.d/90_dpkg.cfg (quiet=False)
2021-11-17 17:59:19,662 - util.py[DEBUG]: Read 309 bytes from /etc/cloud/cloud.cfg.d/90_dpkg.cfg
2021-11-17 17:59:19,662 - util.py[DEBUG]: Attempting to load yaml from string of length 309 with allowed root types (<class 'dict'>,)
2021-11-17 17:59:19,664 - util.py[DEBUG]: Reading from /etc/cloud/cloud.cfg.d/05_logging.cfg (quiet=False)
2021-11-17 17:59:19,664 - util.py[DEBUG]: Read 2070 bytes from /etc/cloud/cloud.cfg.d/05_logging.cfg
2021-11-17 17:59:19,664 - util.py[DEBUG]: Attempting to load yaml from string of length 2070 with allowed root types (<class 'dict'>,)
2021-11-17 17:59:19,667 - util.py[DEBUG]: Reading from /run/cloud-init/cloud.cfg (quiet=False)
2021-11-17 17:59:19,667 - util.py[DEBUG]: Read 35 bytes from /run/cloud-init/cloud.cfg
2021-11-17 17:59:19,667 - util.py[DEBUG]: Attempting to load yaml from string of length 35 with allowed root types (<class 'dict'>,)
2021-11-17 17:59:19,668 - util.py[DEBUG]: Attempting to load yaml from string of length 0 with allowed root types (<class 'dict'>,)
2021-11-17 17:59:19,668 - util.py[DEBUG]: loaded blob returned None, returning default.
2021-11-17 17:59:19,685 - stages.py[DEBUG]: Using distro class <class 'cloudinit.distros.ubuntu.Distro'>
2021-11-17 17:59:19,686 - cc_set_hostname.py[DEBUG]: Setting the hostname to test2 (test2)
2021-11-17 17:59:19,686 - util.py[DEBUG]: Reading from /etc/hostname (quiet=False)
2021-11-17 17:59:19,686 - util.py[DEBUG]: Read 7 bytes from /etc/hostname
2021-11-17 17:59:19,686 - util.py[DEBUG]: Writing to /etc/hostname - wb: [644] 6 bytes
2021-11-17 17:59:19,687 - __init__.py[DEBUG]: Non-persistently setting the system hostname to test2
2021-11-17 17:59:19,687 - subp.py[DEBUG]: Running command ['hostname', 'test2'] with allowed return codes [0] (shell=False, capture=True)
2021-11-17 17:59:19,693 - atomic_helper.py[DEBUG]: Atomically writing to file /var/lib/cloud/data/set-hostname (via temporary file /var/lib/cloud/data/tmp3335xwnf) - w: [644] 43 bytes/chars
2021-11-17 17:59:19,694 - util.py[DEBUG]: Reading from /sys/class/net/enp0s2/address (quiet=False)
2021-11-17 17:59:19,695 - util.py[DEBUG]: Read 18 bytes from /sys/class/net/enp0s2/address
2021-11-17 17:59:19,695 - util.py[DEBUG]: Reading from /sys/class/net/lo/address (quiet=False)
2021-11-17 17:59:19,695 - util.py[DEBUG]: Read 18 bytes from /sys/class/net/lo/address
2021-11-17 17:59:19,695 - util.py[DEBUG]: Reading from /sys/class/net/enp0s2/name_assign_type (quiet=False)
2021-11-17 17:59:19,695 - util.py[DEBUG]: Read 2 bytes from /sys/class/net/enp0s2/name_assign_type
2021-11-17 17:59:19,695 - util.py[DEBUG]: Reading from /sys/class/net/enp0s2/carrier (quiet=False)
2021-11-17 17:59:19,695 - util.py[DEBUG]: Reading from /sys/class/net/enp0s2/dormant (quiet=False)
2021-11-17 17:59:19,696 - util.py[DEBUG]: Reading from /sys/class/net/enp0s2/operstate (quiet=False)
2021-11-17 17:59:19,696 - util.py[DEBUG]: Read 5 bytes from /sys/class/net/enp0s2/operstate
2021-11-17 17:59:19,696 - util.py[DEBUG]: Reading from /sys/class/net/enp0s2/address (quiet=False)
2021-11-17 17:59:19,696 - util.py[DEBUG]: Read 18 bytes from /sys/class/net/enp0s2/address
2021-11-17 17:59:19,696 - util.py[DEBUG]: Reading from /sys/class/net/enp0s2/device/features (quiet=False)
2021-11-17 17:59:19,696 - util.py[DEBUG]: Read 65 bytes from /sys/class/net/enp0s2/device/features
2021-11-17 17:59:19,696 - util.py[DEBUG]: Reading from /sys/class/net/enp0s2/address (quiet=False)
2021-11-17 17:59:19,696 - util.py[DEBUG]: Read 18 bytes from /sys/class/net/enp0s2/address
2021-11-17 17:59:19,696 - util.py[DEBUG]: Reading from /sys/class/net/enp0s2/address (quiet=False)
2021-11-17 17:59:19,696 - util.py[DEBUG]: Read 18 bytes from /sys/class/net/enp0s2/address
2021-11-17 17:59:19,696 - util.py[DEBUG]: Reading from /sys/class/net/lo/address (quiet=False)
2021-11-17 17:59:19,696 - util.py[DEBUG]: Read 18 bytes from /sys/class/net/lo/address
2021-11-17 17:59:19,697 - util.py[DEBUG]: Reading from /sys/class/net/enp0s2/name_assign_type (quiet=False)
2021-11-17 17:59:19,697 - util.py[DEBUG]: Read 2 bytes from /sys/class/net/enp0s2/name_assign_type
2021-11-17 17:59:19,697 - util.py[DEBUG]: Reading from /sys/class/net/enp0s2/carrier (quiet=False)
2021-11-17 17:59:19,697 - util.py[DEBUG]: Reading from /sys/class/net/enp0s2/dormant (quiet=False)
2021-11-17 17:59:19,697 - util.py[DEBUG]: Reading from /sys/class/net/enp0s2/operstate (quiet=False)
2021-11-17 17:59:19,697 - util.py[DEBUG]: Read 5 bytes from /sys/class/net/enp0s2/operstate
2021-11-17 17:59:19,697 - util.py[DEBUG]: Reading from /sys/class/net/enp0s2/address (quiet=False)
2021-11-17 17:59:19,697 - util.py[DEBUG]: Read 18 bytes from /sys/class/net/enp0s2/address
2021-11-17 17:59:19,697 - util.py[DEBUG]: Reading from /sys/class/net/enp0s2/device/features (quiet=False)
2021-11-17 17:59:19,697 - util.py[DEBUG]: Read 65 bytes from /sys/class/net/enp0s2/device/features
2021-11-17 17:59:19,697 - util.py[DEBUG]: Reading from /sys/class/net/enp0s2/address (quiet=False)
2021-11-17 17:59:19,697 - util.py[DEBUG]: Read 18 bytes from /sys/class/net/enp0s2/address
2021-11-17 17:59:19,698 - util.py[DEBUG]: Reading from /sys/class/net/enp0s2/device/device (quiet=False)
2021-11-17 17:59:19,698 - util.py[DEBUG]: Read 7 bytes from /sys/class/net/enp0s2/device/device
2021-11-17 17:59:19,698 - util.py[DEBUG]: Reading from /sys/class/net/enp0s2/addr_assign_type (quiet=False)
2021-11-17 17:59:19,698 - util.py[DEBUG]: Read 2 bytes from /sys/class/net/enp0s2/addr_assign_type
2021-11-17 17:59:19,698 - util.py[DEBUG]: Reading from /sys/class/net/enp0s2/uevent (quiet=False)
2021-11-17 17:59:19,698 - util.py[DEBUG]: Read 27 bytes from /sys/class/net/enp0s2/uevent
2021-11-17 17:59:19,698 - util.py[DEBUG]: Reading from /sys/class/net/enp0s2/address (quiet=False)
2021-11-17 17:59:19,698 - util.py[DEBUG]: Read 18 bytes from /sys/class/net/enp0s2/address
2021-11-17 17:59:19,698 - __init__.py[DEBUG]: ovs-vsctl not in PATH; not detecting Open vSwitch interfaces
2021-11-17 17:59:19,698 - util.py[DEBUG]: Reading from /sys/class/net/enp0s2/device/device (quiet=False)
2021-11-17 17:59:19,698 - util.py[DEBUG]: Read 7 bytes from /sys/class/net/enp0s2/device/device
2021-11-17 17:59:19,698 - util.py[DEBUG]: Reading from /sys/class/net/lo/addr_assign_type (quiet=False)
2021-11-17 17:59:19,698 - util.py[DEBUG]: Read 2 bytes from /sys/class/net/lo/addr_assign_type
2021-11-17 17:59:19,698 - util.py[DEBUG]: Reading from /sys/class/net/lo/uevent (quiet=False)
2021-11-17 17:59:19,699 - util.py[DEBUG]: Read 23 bytes from /sys/class/net/lo/uevent
2021-11-17 17:59:19,699 - util.py[DEBUG]: Reading from /sys/class/net/lo/address (quiet=False)
2021-11-17 17:59:19,699 - util.py[DEBUG]: Read 18 bytes from /sys/class/net/lo/address
2021-11-17 17:59:19,699 - util.py[DEBUG]: Reading from /sys/class/net/lo/device/device (quiet=False)
2021-11-17 17:59:19,699 - util.py[DEBUG]: Reading from /sys/class/net/enp0s2/type (quiet=False)
2021-11-17 17:59:19,699 - util.py[DEBUG]: Read 2 bytes from /sys/class/net/enp0s2/type
2021-11-17 17:59:19,699 - util.py[DEBUG]: Reading from /sys/class/net/lo/type (quiet=False)
2021-11-17 17:59:19,699 - util.py[DEBUG]: Read 4 bytes from /sys/class/net/lo/type
2021-11-17 17:59:19,699 - networking.py[DEBUG]: net: all expected physical devices present
2021-11-17 17:59:19,699 - stages.py[DEBUG]: applying net config names for {'ethernets': {'enp0s2': {'dhcp4': True, 'set-name': 'enp0s2', 'match': {'macaddress': '76:e7:3a:b0:02:e0'}}}, 'version': 2}
2021-11-17 17:59:19,699 - util.py[DEBUG]: Reading from /sys/class/net/enp0s2/device/device (quiet=False)
2021-11-17 17:59:19,699 - util.py[DEBUG]: Read 7 bytes from /sys/class/net/enp0s2/device/device
2021-11-17 17:59:19,699 - util.py[DEBUG]: Reading from /sys/class/net/enp0s2/addr_assign_type (quiet=False)
2021-11-17 17:59:19,699 - util.py[DEBUG]: Read 2 bytes from /sys/class/net/enp0s2/addr_assign_type
2021-11-17 17:59:19,699 - util.py[DEBUG]: Reading from /sys/class/net/enp0s2/uevent (quiet=False)
2021-11-17 17:59:19,699 - util.py[DEBUG]: Read 27 bytes from /sys/class/net/enp0s2/uevent
2021-11-17 17:59:19,700 - util.py[DEBUG]: Reading from /sys/class/net/enp0s2/address (quiet=False)
2021-11-17 17:59:19,700 - util.py[DEBUG]: Read 18 bytes from /sys/class/net/enp0s2/address
2021-11-17 17:59:19,700 - util.py[DEBUG]: Reading from /sys/class/net/enp0s2/device/device (quiet=False)
2021-11-17 17:59:19,700 - util.py[DEBUG]: Read 7 bytes from /sys/class/net/enp0s2/device/device
2021-11-17 17:59:19,700 - util.py[DEBUG]: Reading from /sys/class/net/lo/addr_assign_type (quiet=False)
2021-11-17 17:59:19,700 - util.py[DEBUG]: Read 2 bytes from /sys/class/net/lo/addr_assign_type
2021-11-17 17:59:19,700 - util.py[DEBUG]: Reading from /sys/class/net/lo/uevent (quiet=False)
2021-11-17 17:59:19,700 - util.py[DEBUG]: Read 23 bytes from /sys/class/net/lo/uevent
2021-11-17 17:59:19,700 - util.py[DEBUG]: Reading from /sys/class/net/lo/address (quiet=False)
2021-11-17 17:59:19,700 - util.py[DEBUG]: Read 18 bytes from /sys/class/net/lo/address
2021-11-17 17:59:19,700 - util.py[DEBUG]: Reading from /sys/class/net/lo/device/device (quiet=False)
2021-11-17 17:59:19,700 - util.py[DEBUG]: Reading from /sys/class/net/enp0s2/operstate (quiet=False)
2021-11-17 17:59:19,700 - util.py[DEBUG]: Read 5 bytes from /sys/class/net/enp0s2/operstate
2021-11-17 17:59:19,700 - util.py[DEBUG]: Reading from /sys/class/net/lo/operstate (quiet=False)
2021-11-17 17:59:19,700 - util.py[DEBUG]: Read 8 bytes from /sys/class/net/lo/operstate
2021-11-17 17:59:19,701 - subp.py[DEBUG]: Running command ['ip', '-6', 'addr', 'show', 'permanent', 'scope', 'global'] with allowed return codes [0] (shell=False, capture=True)
2021-11-17 17:59:19,721 - subp.py[DEBUG]: Running command ['ip', '-4', 'addr', 'show'] with allowed return codes [0] (shell=False, capture=True)
2021-11-17 17:59:19,736 - __init__.py[DEBUG]: Detected interfaces {'enp0s2': {'downable': True, 'device_id': '0x0001', 'driver': 'virtio_net', 'mac': '76:e7:3a:b0:02:e0', 'name': 'enp0s2', 'up': False}, 'lo': {'downable': False, 'device_id': None, 'driver': None, 'mac': '00:00:00:00:00:00', 'name': 'lo', 'up': True}}
2021-11-17 17:59:19,736 - __init__.py[DEBUG]: no work necessary for renaming of [['76:e7:3a:b0:02:e0', 'enp0s2', 'virtio_net', '0x0001']]
2021-11-17 17:59:19,736 - stages.py[INFO]: Applying network configuration from fallback bringup=False: {'ethernets': {'enp0s2': {'dhcp4': True, 'set-name': 'enp0s2', 'match': {'macaddress': '76:e7:3a:b0:02:e0'}}}, 'version': 2}
2021-11-17 17:59:19,736 - util.py[DEBUG]: Writing to /run/cloud-init/sem/apply_network_config.once - wb: [644] 24 bytes
2021-11-17 17:59:19,737 - network_state.py[DEBUG]: v2(ethernets) -> v1(physical):
{'type': 'physical', 'name': 'enp0s2', 'mac_address': '76:e7:3a:b0:02:e0', 'match': {'macaddress': '76:e7:3a:b0:02:e0'}, 'subnets': [{'type': 'dhcp4'}]}
2021-11-17 17:59:19,739 - network_state.py[DEBUG]: v2_common: handling config:
{'enp0s2': {'dhcp4': True, 'set-name': 'enp0s2', 'match': {'macaddress': '76:e7:3a:b0:02:e0'}}}
2021-11-17 17:59:19,742 - __init__.py[DEBUG]: Selected renderer 'netplan' from priority list: ['netplan', 'eni', 'sysconfig']
2021-11-17 17:59:19,742 - netplan.py[DEBUG]: V2 to V2 passthrough
2021-11-17 17:59:19,743 - util.py[DEBUG]: Writing to /etc/netplan/50-cloud-init.yaml - wb: [644] 485 bytes
2021-11-17 17:59:19,746 - subp.py[DEBUG]: Running command ['netplan', 'generate'] with allowed return codes [0] (shell=False, capture=True)
2021-11-17 17:59:20,139 - subp.py[DEBUG]: Running command ['udevadm', 'test-builtin', 'net_setup_link', '/sys/class/net/enp0s2'] with allowed return codes [0] (shell=False, capture=True)
2021-11-17 17:59:20,155 - subp.py[DEBUG]: Running command ['udevadm', 'test-builtin', 'net_setup_link', '/sys/class/net/lo'] with allowed return codes [0] (shell=False, capture=True)
2021-11-17 17:59:20,167 - __init__.py[DEBUG]: Not bringing up newly configured network interfaces
2021-11-17 17:59:20,167 - main.py[DEBUG]: [local] Exiting. datasource DataSourceNoCloud [seed=/dev/sr0][dsmode=net] not in local mode.
2021-11-17 17:59:20,167 - atomic_helper.py[DEBUG]: Atomically writing to file /var/lib/cloud/data/status.json (via temporary file /var/lib/cloud/data/tmpi586c5kt) - w: [644] 518 bytes/chars
2021-11-17 17:59:20,168 - util.py[DEBUG]: Reading from /proc/uptime (quiet=False)
2021-11-17 17:59:20,168 - util.py[DEBUG]: Read 11 bytes from /proc/uptime
2021-11-17 17:59:20,168 - util.py[DEBUG]: cloud-init mode 'init' took 1.090 seconds (1.09)
2021-11-17 17:59:20,168 - handlers.py[DEBUG]: finish: init-local: SUCCESS: searching for local datasources
2021-11-17 17:59:22,079 - util.py[DEBUG]: Cloud-init v. 21.3-1-g6803368d-0ubuntu1~20.04.4 running 'init' at Wed, 17 Nov 2021 17:59:22 +0000. Up 12.83 seconds.
2021-11-17 17:59:22,079 - main.py[DEBUG]: No kernel command line url found.
2021-11-17 17:59:22,079 - main.py[DEBUG]: Closing stdin.
2021-11-17 17:59:22,082 - util.py[DEBUG]: Writing to /var/log/cloud-init.log - ab: [644] 0 bytes
2021-11-17 17:59:22,082 - util.py[DEBUG]: Changing the ownership of /var/log/cloud-init.log to 104:4
2021-11-17 17:59:22,083 - subp.py[DEBUG]: Running command ['ip', 'addr', 'show'] with allowed return codes [0] (shell=False, capture=True)
2021-11-17 17:59:22,088 - subp.py[DEBUG]: Running command ['ip', '-o', 'route', 'list'] with allowed return codes [0] (shell=False, capture=True)
2021-11-17 17:59:22,092 - subp.py[DEBUG]: Running command ['ip', '--oneline', '-6', 'route', 'list', 'table', 'all'] with allowed return codes [0, 1] (shell=False, capture=True)
2021-11-17 17:59:22,096 - main.py[DEBUG]: Checking to see if files that we need already exist from a previous run that would allow us to stop early.
2021-11-17 17:59:22,097 - main.py[DEBUG]: Execution continuing, no previous run detected that would allow us to stop early.
2021-11-17 17:59:22,097 - handlers.py[DEBUG]: start: init-network/check-cache: attempting to read from cache [trust]
2021-11-17 17:59:22,097 - util.py[DEBUG]: Reading from /var/lib/cloud/instance/obj.pkl (quiet=False)
2021-11-17 17:59:22,097 - util.py[DEBUG]: Read 7626 bytes from /var/lib/cloud/instance/obj.pkl
2021-11-17 17:59:22,099 - util.py[DEBUG]: Reading from /run/cloud-init/.instance-id (quiet=False)
2021-11-17 17:59:22,099 - util.py[DEBUG]: Read 6 bytes from /run/cloud-init/.instance-id
2021-11-17 17:59:22,099 - stages.py[DEBUG]: restored from cache with run check: DataSourceNoCloud [seed=/dev/sr0][dsmode=net]
2021-11-17 17:59:22,100 - handlers.py[DEBUG]: finish: init-network/check-cache: SUCCESS: restored from cache with run check: DataSourceNoCloud [seed=/dev/sr0][dsmode=net]
2021-11-17 17:59:22,100 - util.py[DEBUG]: Reading from /etc/cloud/cloud.cfg (quiet=False)
2021-11-17 17:59:22,100 - util.py[DEBUG]: Read 3764 bytes from /etc/cloud/cloud.cfg
2021-11-17 17:59:22,100 - util.py[DEBUG]: Attempting to load yaml from string of length 3764 with allowed root types (<class 'dict'>,)
2021-11-17 17:59:22,117 - util.py[DEBUG]: Reading from /etc/cloud/cloud.cfg.d/90_dpkg.cfg (quiet=False)
2021-11-17 17:59:22,117 - util.py[DEBUG]: Read 309 bytes from /etc/cloud/cloud.cfg.d/90_dpkg.cfg
2021-11-17 17:59:22,117 - util.py[DEBUG]: Attempting to load yaml from string of length 309 with allowed root types (<class 'dict'>,)
2021-11-17 17:59:22,119 - util.py[DEBUG]: Reading from /etc/cloud/cloud.cfg.d/05_logging.cfg (quiet=False)
2021-11-17 17:59:22,119 - util.py[DEBUG]: Read 2070 bytes from /etc/cloud/cloud.cfg.d/05_logging.cfg
2021-11-17 17:59:22,119 - util.py[DEBUG]: Attempting to load yaml from string of length 2070 with allowed root types (<class 'dict'>,)
2021-11-17 17:59:22,124 - util.py[DEBUG]: Reading from /run/cloud-init/cloud.cfg (quiet=False)
2021-11-17 17:59:22,124 - util.py[DEBUG]: Read 35 bytes from /run/cloud-init/cloud.cfg
2021-11-17 17:59:22,124 - util.py[DEBUG]: Attempting to load yaml from string of length 35 with allowed root types (<class 'dict'>,)
2021-11-17 17:59:22,125 - util.py[DEBUG]: Attempting to load yaml from string of length 0 with allowed root types (<class 'dict'>,)
2021-11-17 17:59:22,125 - util.py[DEBUG]: loaded blob returned None, returning default.
2021-11-17 17:59:22,126 - util.py[DEBUG]: Attempting to remove /var/lib/cloud/instance
2021-11-17 17:59:22,126 - util.py[DEBUG]: Creating symbolic link from '/var/lib/cloud/instance' => '/var/lib/cloud/instances/test2'
2021-11-17 17:59:22,127 - util.py[DEBUG]: Reading from /var/lib/cloud/instances/test2/datasource (quiet=False)
2021-11-17 17:59:22,127 - util.py[DEBUG]: Read 65 bytes from /var/lib/cloud/instances/test2/datasource
2021-11-17 17:59:22,127 - util.py[DEBUG]: Writing to /var/lib/cloud/instances/test2/datasource - wb: [644] 65 bytes
2021-11-17 17:59:22,131 - util.py[DEBUG]: Writing to /var/lib/cloud/data/previous-datasource - wb: [644] 65 bytes
2021-11-17 17:59:22,133 - util.py[DEBUG]: Reading from /var/lib/cloud/data/instance-id (quiet=False)
2021-11-17 17:59:22,133 - util.py[DEBUG]: Read 6 bytes from /var/lib/cloud/data/instance-id
2021-11-17 17:59:22,133 - stages.py[DEBUG]: previous iid found to be test2
2021-11-17 17:59:22,133 - util.py[DEBUG]: Writing to /var/lib/cloud/data/instance-id - wb: [644] 6 bytes
2021-11-17 17:59:22,134 - util.py[DEBUG]: Writing to /run/cloud-init/.instance-id - wb: [644] 6 bytes
2021-11-17 17:59:22,134 - util.py[DEBUG]: Writing to /var/lib/cloud/data/previous-instance-id - wb: [644] 6 bytes
2021-11-17 17:59:22,135 - util.py[DEBUG]: Writing to /var/lib/cloud/instance/obj.pkl - wb: [400] 7638 bytes
2021-11-17 17:59:22,137 - main.py[DEBUG]: [net] init will now be targeting instance id: test2. new=False
2021-11-17 17:59:22,137 - util.py[DEBUG]: Reading from /etc/cloud/cloud.cfg (quiet=False)
2021-11-17 17:59:22,137 - util.py[DEBUG]: Read 3764 bytes from /etc/cloud/cloud.cfg
2021-11-17 17:59:22,137 - util.py[DEBUG]: Attempting to load yaml from string of length 3764 with allowed root types (<class 'dict'>,)
2021-11-17 17:59:22,150 - util.py[DEBUG]: Reading from /etc/cloud/cloud.cfg.d/90_dpkg.cfg (quiet=False)
2021-11-17 17:59:22,150 - util.py[DEBUG]: Read 309 bytes from /etc/cloud/cloud.cfg.d/90_dpkg.cfg
2021-11-17 17:59:22,150 - util.py[DEBUG]: Attempting to load yaml from string of length 309 with allowed root types (<class 'dict'>,)
2021-11-17 17:59:22,152 - util.py[DEBUG]: Reading from /etc/cloud/cloud.cfg.d/05_logging.cfg (quiet=False)
2021-11-17 17:59:22,152 - util.py[DEBUG]: Read 2070 bytes from /etc/cloud/cloud.cfg.d/05_logging.cfg
2021-11-17 17:59:22,152 - util.py[DEBUG]: Attempting to load yaml from string of length 2070 with allowed root types (<class 'dict'>,)
2021-11-17 17:59:22,155 - util.py[DEBUG]: Reading from /run/cloud-init/cloud.cfg (quiet=False)
2021-11-17 17:59:22,155 - util.py[DEBUG]: Read 35 bytes from /run/cloud-init/cloud.cfg
2021-11-17 17:59:22,155 - util.py[DEBUG]: Attempting to load yaml from string of length 35 with allowed root types (<class 'dict'>,)
2021-11-17 17:59:22,156 - util.py[DEBUG]: Attempting to load yaml from string of length 0 with allowed root types (<class 'dict'>,)
2021-11-17 17:59:22,156 - util.py[DEBUG]: loaded blob returned None, returning default.
2021-11-17 17:59:22,157 - util.py[DEBUG]: Reading from /sys/class/net/enp0s2/address (quiet=False)
2021-11-17 17:59:22,157 - util.py[DEBUG]: Read 18 bytes from /sys/class/net/enp0s2/address
2021-11-17 17:59:22,157 - util.py[DEBUG]: Reading from /sys/class/net/lo/address (quiet=False)
2021-11-17 17:59:22,157 - util.py[DEBUG]: Read 18 bytes from /sys/class/net/lo/address
2021-11-17 17:59:22,158 - stages.py[DEBUG]: Using distro class <class 'cloudinit.distros.ubuntu.Distro'>
2021-11-17 17:59:22,158 - util.py[DEBUG]: Reading from /sys/class/net/enp0s2/name_assign_type (quiet=False)
2021-11-17 17:59:22,158 - util.py[DEBUG]: Read 2 bytes from /sys/class/net/enp0s2/name_assign_type
2021-11-17 17:59:22,158 - util.py[DEBUG]: Reading from /sys/class/net/enp0s2/carrier (quiet=False)
2021-11-17 17:59:22,159 - util.py[DEBUG]: Read 2 bytes from /sys/class/net/enp0s2/carrier
2021-11-17 17:59:22,159 - util.py[DEBUG]: Reading from /sys/class/net/enp0s2/address (quiet=False)
2021-11-17 17:59:22,159 - util.py[DEBUG]: Read 18 bytes from /sys/class/net/enp0s2/address
2021-11-17 17:59:22,159 - util.py[DEBUG]: Reading from /sys/class/net/enp0s2/device/features (quiet=False)
2021-11-17 17:59:22,159 - util.py[DEBUG]: Read 65 bytes from /sys/class/net/enp0s2/device/features
2021-11-17 17:59:22,159 - util.py[DEBUG]: Reading from /sys/class/net/enp0s2/address (quiet=False)
2021-11-17 17:59:22,159 - util.py[DEBUG]: Read 18 bytes from /sys/class/net/enp0s2/address
2021-11-17 17:59:22,160 - stages.py[DEBUG]: Allowed events: {<EventScope.NETWORK: 'network'>: {<EventType.BOOT_NEW_INSTANCE: 'boot-new-instance'>}}
2021-11-17 17:59:22,160 - stages.py[DEBUG]: Event Denied: scopes=['network'] EventType=boot-legacy
2021-11-17 17:59:22,160 - stages.py[DEBUG]: No network config applied. Neither a new instance nor datasource network update allowed
2021-11-17 17:59:22,160 - stages.py[DEBUG]: applying net config names for {'ethernets': {'enp0s2': {'dhcp4': True, 'set-name': 'enp0s2', 'match': {'macaddress': '76:e7:3a:b0:02:e0'}}}, 'version': 2}
2021-11-17 17:59:22,160 - util.py[DEBUG]: Reading from /sys/class/net/enp0s2/device/device (quiet=False)
2021-11-17 17:59:22,160 - util.py[DEBUG]: Read 7 bytes from /sys/class/net/enp0s2/device/device
2021-11-17 17:59:22,160 - util.py[DEBUG]: Reading from /sys/class/net/enp0s2/addr_assign_type (quiet=False)
2021-11-17 17:59:22,160 - util.py[DEBUG]: Read 2 bytes from /sys/class/net/enp0s2/addr_assign_type
2021-11-17 17:59:22,160 - util.py[DEBUG]: Reading from /sys/class/net/enp0s2/uevent (quiet=False)
2021-11-17 17:59:22,160 - util.py[DEBUG]: Read 27 bytes from /sys/class/net/enp0s2/uevent
2021-11-17 17:59:22,160 - util.py[DEBUG]: Reading from /sys/class/net/enp0s2/address (quiet=False)
2021-11-17 17:59:22,160 - util.py[DEBUG]: Read 18 bytes from /sys/class/net/enp0s2/address
2021-11-17 17:59:22,161 - __init__.py[DEBUG]: ovs-vsctl not in PATH; not detecting Open vSwitch interfaces
2021-11-17 17:59:22,161 - util.py[DEBUG]: Reading from /sys/class/net/enp0s2/device/device (quiet=False)
2021-11-17 17:59:22,161 - util.py[DEBUG]: Read 7 bytes from /sys/class/net/enp0s2/device/device
2021-11-17 17:59:22,161 - util.py[DEBUG]: Reading from /sys/class/net/lo/addr_assign_type (quiet=False)
2021-11-17 17:59:22,161 - util.py[DEBUG]: Read 2 bytes from /sys/class/net/lo/addr_assign_type
2021-11-17 17:59:22,161 - util.py[DEBUG]: Reading from /sys/class/net/lo/uevent (quiet=False)
2021-11-17 17:59:22,161 - util.py[DEBUG]: Read 23 bytes from /sys/class/net/lo/uevent
2021-11-17 17:59:22,161 - util.py[DEBUG]: Reading from /sys/class/net/lo/address (quiet=False)
2021-11-17 17:59:22,161 - util.py[DEBUG]: Read 18 bytes from /sys/class/net/lo/address
2021-11-17 17:59:22,161 - util.py[DEBUG]: Reading from /sys/class/net/lo/device/device (quiet=False)
2021-11-17 17:59:22,161 - util.py[DEBUG]: Reading from /sys/class/net/enp0s2/operstate (quiet=False)
2021-11-17 17:59:22,161 - util.py[DEBUG]: Read 3 bytes from /sys/class/net/enp0s2/operstate
2021-11-17 17:59:22,161 - util.py[DEBUG]: Reading from /sys/class/net/lo/operstate (quiet=False)
2021-11-17 17:59:22,161 - util.py[DEBUG]: Read 8 bytes from /sys/class/net/lo/operstate
2021-11-17 17:59:22,162 - subp.py[DEBUG]: Running command ['ip', '-6', 'addr', 'show', 'permanent', 'scope', 'global'] with allowed return codes [0] (shell=False, capture=True)
2021-11-17 17:59:22,165 - subp.py[DEBUG]: Running command ['ip', '-4', 'addr', 'show'] with allowed return codes [0] (shell=False, capture=True)
2021-11-17 17:59:22,168 - __init__.py[DEBUG]: Detected interfaces {'enp0s2': {'downable': False, 'device_id': '0x0001', 'driver': 'virtio_net', 'mac': '76:e7:3a:b0:02:e0', 'name': 'enp0s2', 'up': True}, 'lo': {'downable': False, 'device_id': None, 'driver': None, 'mac': '00:00:00:00:00:00', 'name': 'lo', 'up': True}}
2021-11-17 17:59:22,168 - __init__.py[DEBUG]: no work necessary for renaming of [['76:e7:3a:b0:02:e0', 'enp0s2', 'virtio_net', '0x0001']]
2021-11-17 17:59:22,169 - handlers.py[DEBUG]: start: init-network/setup-datasource: setting up datasource
2021-11-17 17:59:22,169 - handlers.py[DEBUG]: finish: init-network/setup-datasource: SUCCESS: setting up datasource
2021-11-17 17:59:22,169 - util.py[DEBUG]: Writing to /var/lib/cloud/instances/test2/user-data.txt - wb: [600] 1112 bytes
2021-11-17 17:59:22,170 - util.py[DEBUG]: Attempting to load yaml from string of length 1112 with allowed root types (<class 'dict'>,)
2021-11-17 17:59:22,177 - util.py[DEBUG]: Writing to /var/lib/cloud/instances/test2/user-data.txt.i - wb: [600] 1417 bytes
2021-11-17 17:59:22,178 - util.py[DEBUG]: Writing to /var/lib/cloud/instances/test2/vendor-data.txt - wb: [600] 840 bytes
2021-11-17 17:59:22,178 - util.py[DEBUG]: Attempting to load yaml from string of length 840 with allowed root types (<class 'dict'>,)
2021-11-17 17:59:22,182 - util.py[DEBUG]: Writing to /var/lib/cloud/instances/test2/vendor-data.txt.i - wb: [600] 1145 bytes
2021-11-17 17:59:22,183 - util.py[DEBUG]: Writing to /var/lib/cloud/instances/test2/vendor-data2.txt - wb: [600] 0 bytes
2021-11-17 17:59:22,184 - util.py[DEBUG]: Writing to /var/lib/cloud/instances/test2/vendor-data2.txt.i - wb: [600] 308 bytes
2021-11-17 17:59:22,185 - util.py[DEBUG]: Reading from /var/lib/cloud/data/set-hostname (quiet=False)
2021-11-17 17:59:22,185 - util.py[DEBUG]: Read 43 bytes from /var/lib/cloud/data/set-hostname
2021-11-17 17:59:22,185 - cc_set_hostname.py[DEBUG]: No hostname changes. Skipping set-hostname
2021-11-17 17:59:22,186 - util.py[DEBUG]: Writing to /var/lib/cloud/instances/test2/sem/consume_data - wb: [644] 24 bytes
2021-11-17 17:59:22,186 - helpers.py[DEBUG]: Running consume_data using lock (<FileLock using file '/var/lib/cloud/instances/test2/sem/consume_data'>)
2021-11-17 17:59:22,186 - handlers.py[DEBUG]: start: init-network/consume-user-data: reading and applying user-data
2021-11-17 17:59:22,187 - stages.py[DEBUG]: Added default handler for {'text/cloud-config', 'text/cloud-config-jsonp'} from CloudConfigPartHandler: [['text/cloud-config', 'text/cloud-config-jsonp']]
2021-11-17 17:59:22,187 - stages.py[DEBUG]: Added default handler for {'text/x-shellscript'} from ShellScriptPartHandler: [['text/x-shellscript']]
2021-11-17 17:59:22,187 - stages.py[DEBUG]: Added default handler for {'text/cloud-boothook'} from BootHookPartHandler: [['text/cloud-boothook']]
2021-11-17 17:59:22,187 - stages.py[DEBUG]: Added default handler for {'text/upstart-job'} from UpstartJobPartHandler: [['text/upstart-job']]
2021-11-17 17:59:22,187 - stages.py[DEBUG]: Added default handler for {'text/jinja2'} from JinjaTemplatePartHandler: [['text/jinja2']]
2021-11-17 17:59:22,187 - __init__.py[DEBUG]: Calling handler CloudConfigPartHandler: [['text/cloud-config', 'text/cloud-config-jsonp']] (__begin__, None, 3) with frequency once-per-instance
2021-11-17 17:59:22,187 - __init__.py[DEBUG]: Calling handler ShellScriptPartHandler: [['text/x-shellscript']] (__begin__, None, 2) with frequency once-per-instance
2021-11-17 17:59:22,187 - __init__.py[DEBUG]: Calling handler BootHookPartHandler: [['text/cloud-boothook']] (__begin__, None, 2) with frequency once-per-instance
2021-11-17 17:59:22,187 - __init__.py[DEBUG]: Calling handler UpstartJobPartHandler: [['text/upstart-job']] (__begin__, None, 2) with frequency once-per-instance
2021-11-17 17:59:22,187 - __init__.py[DEBUG]: Calling handler JinjaTemplatePartHandler: [['text/jinja2']] (__begin__, None, 3) with frequency once-per-instance
2021-11-17 17:59:22,187 - __init__.py[DEBUG]: {'MIME-Version': '1.0', 'Content-Type': 'text/cloud-config', 'Content-Disposition': 'attachment; filename="part-001"'}
2021-11-17 17:59:22,187 - __init__.py[DEBUG]: Calling handler CloudConfigPartHandler: [['text/cloud-config', 'text/cloud-config-jsonp']] (text/cloud-config, part-001, 3) with frequency once-per-instance
2021-11-17 17:59:22,187 - util.py[DEBUG]: Attempting to load yaml from string of length 1112 with allowed root types (<class 'dict'>,)
2021-11-17 17:59:22,191 - cloud_config.py[DEBUG]: Merging by applying [('dict', ['replace']), ('list', []), ('str', [])]
2021-11-17 17:59:22,191 - __init__.py[DEBUG]: Calling handler CloudConfigPartHandler: [['text/cloud-config', 'text/cloud-config-jsonp']] (__end__, None, 3) with frequency once-per-instance
2021-11-17 17:59:22,194 - util.py[DEBUG]: Writing to /var/lib/cloud/instances/test2/cloud-config.txt - wb: [600] 1142 bytes
2021-11-17 17:59:22,195 - __init__.py[DEBUG]: Calling handler ShellScriptPartHandler: [['text/x-shellscript']] (__end__, None, 2) with frequency once-per-instance
2021-11-17 17:59:22,195 - __init__.py[DEBUG]: Calling handler BootHookPartHandler: [['text/cloud-boothook']] (__end__, None, 2) with frequency once-per-instance
2021-11-17 17:59:22,195 - __init__.py[DEBUG]: Calling handler UpstartJobPartHandler: [['text/upstart-job']] (__end__, None, 2) with frequency once-per-instance
2021-11-17 17:59:22,195 - __init__.py[DEBUG]: Calling handler JinjaTemplatePartHandler: [['text/jinja2']] (__end__, None, 3) with frequency once-per-instance
2021-11-17 17:59:22,195 - handlers.py[DEBUG]: finish: init-network/consume-user-data: SUCCESS: reading and applying user-data
2021-11-17 17:59:22,195 - handlers.py[DEBUG]: start: init-network/consume-vendor-data: reading and applying vendor-data
2021-11-17 17:59:22,196 - util.py[DEBUG]: Reading from /var/lib/cloud/instance/cloud-config.txt (quiet=False)
2021-11-17 17:59:22,196 - util.py[DEBUG]: Read 1142 bytes from /var/lib/cloud/instance/cloud-config.txt
2021-11-17 17:59:22,196 - util.py[DEBUG]: Attempting to load yaml from string of length 1142 with allowed root types (<class 'dict'>,)
2021-11-17 17:59:22,199 - stages.py[DEBUG]: vendordata will be consumed. disabled_handlers=None
2021-11-17 17:59:22,199 - stages.py[DEBUG]: Added default handler for {'text/cloud-config', 'text/cloud-config-jsonp'} from CloudConfigPartHandler: [['text/cloud-config', 'text/cloud-config-jsonp']]
2021-11-17 17:59:22,199 - stages.py[DEBUG]: Added default handler for {'text/x-shellscript'} from ShellScriptPartHandler: [['text/x-shellscript']]
2021-11-17 17:59:22,199 - stages.py[DEBUG]: Added default handler for {'text/cloud-boothook'} from BootHookPartHandler: [['text/cloud-boothook']]
2021-11-17 17:59:22,200 - stages.py[DEBUG]: Added default handler for {'text/upstart-job'} from UpstartJobPartHandler: [['text/upstart-job']]
2021-11-17 17:59:22,200 - stages.py[DEBUG]: Added default handler for {'text/jinja2'} from JinjaTemplatePartHandler: [['text/jinja2']]
2021-11-17 17:59:22,200 - __init__.py[DEBUG]: Calling handler CloudConfigPartHandler: [['text/cloud-config', 'text/cloud-config-jsonp']] (__begin__, None, 3) with frequency once-per-instance
2021-11-17 17:59:22,200 - __init__.py[DEBUG]: Calling handler ShellScriptPartHandler: [['text/x-shellscript']] (__begin__, None, 2) with frequency once-per-instance
2021-11-17 17:59:22,200 - __init__.py[DEBUG]: Calling handler BootHookPartHandler: [['text/cloud-boothook']] (__begin__, None, 2) with frequency once-per-instance
2021-11-17 17:59:22,200 - __init__.py[DEBUG]: Calling handler UpstartJobPartHandler: [['text/upstart-job']] (__begin__, None, 2) with frequency once-per-instance
2021-11-17 17:59:22,200 - __init__.py[DEBUG]: Calling handler JinjaTemplatePartHandler: [['text/jinja2']] (__begin__, None, 3) with frequency once-per-instance
2021-11-17 17:59:22,200 - __init__.py[DEBUG]: {'MIME-Version': '1.0', 'Content-Type': 'text/cloud-config', 'Content-Disposition': 'attachment; filename="part-001"'}
2021-11-17 17:59:22,200 - __init__.py[DEBUG]: Calling handler CloudConfigPartHandler: [['text/cloud-config', 'text/cloud-config-jsonp']] (text/cloud-config, part-001, 3) with frequency once-per-instance
2021-11-17 17:59:22,200 - util.py[DEBUG]: Attempting to load yaml from string of length 840 with allowed root types (<class 'dict'>,)
2021-11-17 17:59:22,203 - cloud_config.py[DEBUG]: Merging by applying [('dict', ['replace']), ('list', []), ('str', [])]
2021-11-17 17:59:22,203 - __init__.py[DEBUG]: Calling handler CloudConfigPartHandler: [['text/cloud-config', 'text/cloud-config-jsonp']] (__end__, None, 3) with frequency once-per-instance
2021-11-17 17:59:22,205 - util.py[DEBUG]: Writing to /var/lib/cloud/instances/test2/vendor-cloud-config.txt - wb: [600] 915 bytes
2021-11-17 17:59:22,205 - __init__.py[DEBUG]: Calling handler ShellScriptPartHandler: [['text/x-shellscript']] (__end__, None, 2) with frequency once-per-instance
2021-11-17 17:59:22,205 - __init__.py[DEBUG]: Calling handler BootHookPartHandler: [['text/cloud-boothook']] (__end__, None, 2) with frequency once-per-instance
2021-11-17 17:59:22,205 - __init__.py[DEBUG]: Calling handler UpstartJobPartHandler: [['text/upstart-job']] (__end__, None, 2) with frequency once-per-instance
2021-11-17 17:59:22,206 - __init__.py[DEBUG]: Calling handler JinjaTemplatePartHandler: [['text/jinja2']] (__end__, None, 3) with frequency once-per-instance
2021-11-17 17:59:22,206 - handlers.py[DEBUG]: finish: init-network/consume-vendor-data: SUCCESS: reading and applying vendor-data
2021-11-17 17:59:22,206 - handlers.py[DEBUG]: start: init-network/consume-vendor-data2: reading and applying vendor-data2
2021-11-17 17:59:22,206 - stages.py[DEBUG]: no vendordata2 from datasource
2021-11-17 17:59:22,206 - handlers.py[DEBUG]: finish: init-network/consume-vendor-data2: SUCCESS: reading and applying vendor-data2
2021-11-17 17:59:22,206 - util.py[DEBUG]: Reading from /etc/cloud/cloud.cfg (quiet=False)
2021-11-17 17:59:22,207 - util.py[DEBUG]: Read 3764 bytes from /etc/cloud/cloud.cfg
2021-11-17 17:59:22,207 - util.py[DEBUG]: Attempting to load yaml from string of length 3764 with allowed root types (<class 'dict'>,)
2021-11-17 17:59:22,226 - util.py[DEBUG]: Reading from /etc/cloud/cloud.cfg.d/90_dpkg.cfg (quiet=False)
2021-11-17 17:59:22,227 - util.py[DEBUG]: Read 309 bytes from /etc/cloud/cloud.cfg.d/90_dpkg.cfg
2021-11-17 17:59:22,227 - util.py[DEBUG]: Attempting to load yaml from string of length 309 with allowed root types (<class 'dict'>,)
2021-11-17 17:59:22,229 - util.py[DEBUG]: Reading from /etc/cloud/cloud.cfg.d/05_logging.cfg (quiet=False)
2021-11-17 17:59:22,229 - util.py[DEBUG]: Read 2070 bytes from /etc/cloud/cloud.cfg.d/05_logging.cfg
2021-11-17 17:59:22,229 - util.py[DEBUG]: Attempting to load yaml from string of length 2070 with allowed root types (<class 'dict'>,)
2021-11-17 17:59:22,232 - util.py[DEBUG]: Reading from /run/cloud-init/cloud.cfg (quiet=False)
2021-11-17 17:59:22,232 - util.py[DEBUG]: Read 35 bytes from /run/cloud-init/cloud.cfg
2021-11-17 17:59:22,232 - util.py[DEBUG]: Attempting to load yaml from string of length 35 with allowed root types (<class 'dict'>,)
2021-11-17 17:59:22,233 - util.py[DEBUG]: Attempting to load yaml from string of length 0 with allowed root types (<class 'dict'>,)
2021-11-17 17:59:22,233 - util.py[DEBUG]: loaded blob returned None, returning default.
2021-11-17 17:59:22,233 - util.py[DEBUG]: Reading from /var/lib/cloud/instance/cloud-config.txt (quiet=False)
2021-11-17 17:59:22,233 - util.py[DEBUG]: Read 1142 bytes from /var/lib/cloud/instance/cloud-config.txt
2021-11-17 17:59:22,233 - util.py[DEBUG]: Attempting to load yaml from string of length 1142 with allowed root types (<class 'dict'>,)
2021-11-17 17:59:22,237 - util.py[DEBUG]: Reading from /var/lib/cloud/instance/vendor-cloud-config.txt (quiet=False)
2021-11-17 17:59:22,237 - util.py[DEBUG]: Read 915 bytes from /var/lib/cloud/instance/vendor-cloud-config.txt
2021-11-17 17:59:22,237 - util.py[DEBUG]: Attempting to load yaml from string of length 915 with allowed root types (<class 'dict'>,)
2021-11-17 17:59:22,241 - util.py[DEBUG]: Reading from /var/lib/cloud/instance/cloud-config.txt (quiet=False)
2021-11-17 17:59:22,241 - util.py[DEBUG]: Read 1142 bytes from /var/lib/cloud/instance/cloud-config.txt
2021-11-17 17:59:22,241 - util.py[DEBUG]: Attempting to load yaml from string of length 1142 with allowed root types (<class 'dict'>,)
2021-11-17 17:59:22,244 - util.py[DEBUG]: Reading from /var/lib/cloud/instance/vendor-cloud-config.txt (quiet=False)
2021-11-17 17:59:22,244 - util.py[DEBUG]: Read 915 bytes from /var/lib/cloud/instance/vendor-cloud-config.txt
2021-11-17 17:59:22,244 - util.py[DEBUG]: Attempting to load yaml from string of length 915 with allowed root types (<class 'dict'>,)
2021-11-17 17:59:22,254 - handlers.py[DEBUG]: start: init-network/activate-datasource: activating datasource
2021-11-17 17:59:22,254 - util.py[DEBUG]: Writing to /var/lib/cloud/instance/obj.pkl - wb: [400] 11666 bytes
2021-11-17 17:59:22,255 - handlers.py[DEBUG]: finish: init-network/activate-datasource: SUCCESS: activating datasource
2021-11-17 17:59:22,256 - main.py[DEBUG]: no di_report found in config.
2021-11-17 17:59:22,292 - stages.py[DEBUG]: Using distro class <class 'cloudinit.distros.ubuntu.Distro'>
2021-11-17 17:59:22,293 - stages.py[DEBUG]: Running module migrator (<module 'cloudinit.config.cc_migrator' from '/usr/lib/python3/dist-packages/cloudinit/config/cc_migrator.py'>) with frequency always
2021-11-17 17:59:22,293 - handlers.py[DEBUG]: start: init-network/config-migrator: running config-migrator with frequency always
2021-11-17 17:59:22,293 - helpers.py[DEBUG]: Running config-migrator using lock (<cloudinit.helpers.DummyLock object at 0x7fe21c4f3be0>)
2021-11-17 17:59:22,293 - cc_migrator.py[DEBUG]: Migrated 0 semaphore files to there canonicalized names
2021-11-17 17:59:22,294 - handlers.py[DEBUG]: finish: init-network/config-migrator: SUCCESS: config-migrator ran successfully
2021-11-17 17:59:22,294 - stages.py[DEBUG]: Running module seed_random (<module 'cloudinit.config.cc_seed_random' from '/usr/lib/python3/dist-packages/cloudinit/config/cc_seed_random.py'>) with frequency once-per-instance
2021-11-17 17:59:22,294 - handlers.py[DEBUG]: start: init-network/config-seed_random: running config-seed_random with frequency once-per-instance
2021-11-17 17:59:22,294 - util.py[DEBUG]: Writing to /var/lib/cloud/instances/test2/sem/config_seed_random - wb: [644] 24 bytes
2021-11-17 17:59:22,295 - helpers.py[DEBUG]: Running config-seed_random using lock (<FileLock using file '/var/lib/cloud/instances/test2/sem/config_seed_random'>)
2021-11-17 17:59:22,295 - cc_seed_random.py[DEBUG]: no command provided
2021-11-17 17:59:22,295 - handlers.py[DEBUG]: finish: init-network/config-seed_random: SUCCESS: config-seed_random ran successfully
2021-11-17 17:59:22,295 - stages.py[DEBUG]: Running module bootcmd (<module 'cloudinit.config.cc_bootcmd' from '/usr/lib/python3/dist-packages/cloudinit/config/cc_bootcmd.py'>) with frequency always
2021-11-17 17:59:22,295 - handlers.py[DEBUG]: start: init-network/config-bootcmd: running config-bootcmd with frequency always
2021-11-17 17:59:22,295 - helpers.py[DEBUG]: Running config-bootcmd using lock (<cloudinit.helpers.DummyLock object at 0x7fe21c4f3970>)
2021-11-17 17:59:22,295 - cc_bootcmd.py[DEBUG]: Skipping module named bootcmd, no 'bootcmd' key in configuration
2021-11-17 17:59:22,295 - handlers.py[DEBUG]: finish: init-network/config-bootcmd: SUCCESS: config-bootcmd ran successfully
2021-11-17 17:59:22,295 - stages.py[DEBUG]: Running module write-files (<module 'cloudinit.config.cc_write_files' from '/usr/lib/python3/dist-packages/cloudinit/config/cc_write_files.py'>) with frequency once-per-instance
2021-11-17 17:59:22,299 - handlers.py[DEBUG]: start: init-network/config-write-files: running config-write-files with frequency once-per-instance
2021-11-17 17:59:22,299 - util.py[DEBUG]: Writing to /var/lib/cloud/instances/test2/sem/config_write_files - wb: [644] 24 bytes
2021-11-17 17:59:22,299 - helpers.py[DEBUG]: Running config-write-files using lock (<FileLock using file '/var/lib/cloud/instances/test2/sem/config_write_files'>)
2021-11-17 17:59:22,375 - util.py[DEBUG]: Writing to /etc/pollinate/add-user-agent - wb: [644] 147 bytes
2021-11-17 17:59:22,377 - util.py[DEBUG]: Changing the ownership of /etc/pollinate/add-user-agent to 0:0
2021-11-17 17:59:22,377 - handlers.py[DEBUG]: finish: init-network/config-write-files: SUCCESS: config-write-files ran successfully
2021-11-17 17:59:22,377 - stages.py[DEBUG]: Running module growpart (<module 'cloudinit.config.cc_growpart' from '/usr/lib/python3/dist-packages/cloudinit/config/cc_growpart.py'>) with frequency always
2021-11-17 17:59:22,377 - handlers.py[DEBUG]: start: init-network/config-growpart: running config-growpart with frequency always
2021-11-17 17:59:22,377 - helpers.py[DEBUG]: Running config-growpart using lock (<cloudinit.helpers.DummyLock object at 0x7fe21c4f33a0>)
2021-11-17 17:59:22,378 - subp.py[DEBUG]: Running command ['growpart', '--help'] with allowed return codes [0] (shell=False, capture=True)
2021-11-17 17:59:22,383 - util.py[DEBUG]: Reading from /proc/577/mountinfo (quiet=False)
2021-11-17 17:59:22,383 - util.py[DEBUG]: Read 3551 bytes from /proc/577/mountinfo
2021-11-17 17:59:22,384 - util.py[DEBUG]: Reading from /sys/class/block/vda1/partition (quiet=False)
2021-11-17 17:59:22,384 - util.py[DEBUG]: Read 2 bytes from /sys/class/block/vda1/partition
2021-11-17 17:59:22,384 - util.py[DEBUG]: Reading from /sys/devices/pci0000:00/0000:00:01.0/virtio0/block/vda/dev (quiet=False)
2021-11-17 17:59:22,384 - util.py[DEBUG]: Read 6 bytes from /sys/devices/pci0000:00/0000:00:01.0/virtio0/block/vda/dev
2021-11-17 17:59:22,384 - subp.py[DEBUG]: Running command ['growpart', '--dry-run', '/dev/vda', '1'] with allowed return codes [0] (shell=False, capture=True)
2021-11-17 17:59:22,441 - subp.py[DEBUG]: Running command ['growpart', '/dev/vda', '1'] with allowed return codes [0] (shell=False, capture=True)
2021-11-17 17:59:22,834 - util.py[DEBUG]: resize_devices took 0.451 seconds
2021-11-17 17:59:22,834 - cc_growpart.py[INFO]: '/' resized: changed (/dev/vda, 1) from 2244984320 to 5252300288
2021-11-17 17:59:22,835 - handlers.py[DEBUG]: finish: init-network/config-growpart: SUCCESS: config-growpart ran successfully
2021-11-17 17:59:22,835 - stages.py[DEBUG]: Running module resizefs (<module 'cloudinit.config.cc_resizefs' from '/usr/lib/python3/dist-packages/cloudinit/config/cc_resizefs.py'>) with frequency always
2021-11-17 17:59:22,835 - handlers.py[DEBUG]: start: init-network/config-resizefs: running config-resizefs with frequency always
2021-11-17 17:59:22,835 - helpers.py[DEBUG]: Running config-resizefs using lock (<cloudinit.helpers.DummyLock object at 0x7fe21c4f33a0>)
2021-11-17 17:59:22,836 - util.py[DEBUG]: Reading from /proc/577/mountinfo (quiet=False)
2021-11-17 17:59:22,836 - util.py[DEBUG]: Read 3551 bytes from /proc/577/mountinfo
2021-11-17 17:59:22,836 - cc_resizefs.py[DEBUG]: resize_info: dev=/dev/vda1 mnt_point=/ path=/
2021-11-17 17:59:22,836 - cc_resizefs.py[DEBUG]: Resizing / (ext4) using resize2fs /dev/vda1
2021-11-17 17:59:22,836 - subp.py[DEBUG]: Running command ('resize2fs', '/dev/vda1') with allowed return codes [0] (shell=False, capture=True)
2021-11-17 17:59:22,902 - util.py[DEBUG]: Resizing took 0.065 seconds
2021-11-17 17:59:22,902 - cc_resizefs.py[DEBUG]: Resized root filesystem (type=ext4, val=True)
2021-11-17 17:59:22,902 - handlers.py[DEBUG]: finish: init-network/config-resizefs: SUCCESS: config-resizefs ran successfully
2021-11-17 17:59:22,902 - stages.py[DEBUG]: Running module disk_setup (<module 'cloudinit.config.cc_disk_setup' from '/usr/lib/python3/dist-packages/cloudinit/config/cc_disk_setup.py'>) with frequency once-per-instance
2021-11-17 17:59:22,903 - handlers.py[DEBUG]: start: init-network/config-disk_setup: running config-disk_setup with frequency once-per-instance
2021-11-17 17:59:22,903 - util.py[DEBUG]: Writing to /var/lib/cloud/instances/test2/sem/config_disk_setup - wb: [644] 24 bytes
2021-11-17 17:59:22,903 - helpers.py[DEBUG]: Running config-disk_setup using lock (<FileLock using file '/var/lib/cloud/instances/test2/sem/config_disk_setup'>)
2021-11-17 17:59:22,904 - handlers.py[DEBUG]: finish: init-network/config-disk_setup: SUCCESS: config-disk_setup ran successfully
2021-11-17 17:59:22,904 - stages.py[DEBUG]: Running module mounts (<module 'cloudinit.config.cc_mounts' from '/usr/lib/python3/dist-packages/cloudinit/config/cc_mounts.py'>) with frequency once-per-instance
2021-11-17 17:59:22,904 - handlers.py[DEBUG]: start: init-network/config-mounts: running config-mounts with frequency once-per-instance
2021-11-17 17:59:22,904 - util.py[DEBUG]: Writing to /var/lib/cloud/instances/test2/sem/config_mounts - wb: [644] 24 bytes
2021-11-17 17:59:22,904 - helpers.py[DEBUG]: Running config-mounts using lock (<FileLock using file '/var/lib/cloud/instances/test2/sem/config_mounts'>)
2021-11-17 17:59:22,905 - cc_mounts.py[DEBUG]: mounts configuration is []
2021-11-17 17:59:22,905 - util.py[DEBUG]: Reading from /etc/fstab (quiet=False)
2021-11-17 17:59:22,905 - util.py[DEBUG]: Read 84 bytes from /etc/fstab
2021-11-17 17:59:22,905 - cc_mounts.py[DEBUG]: Attempting to determine the real name of ephemeral0
2021-11-17 17:59:22,905 - cc_mounts.py[DEBUG]: changed default device ephemeral0 => None
2021-11-17 17:59:22,905 - cc_mounts.py[DEBUG]: Ignoring nonexistent default named mount ephemeral0
2021-11-17 17:59:22,905 - cc_mounts.py[DEBUG]: Attempting to determine the real name of swap
2021-11-17 17:59:22,905 - cc_mounts.py[DEBUG]: changed default device swap => None
2021-11-17 17:59:22,905 - cc_mounts.py[DEBUG]: Ignoring nonexistent default named mount swap
2021-11-17 17:59:22,905 - cc_mounts.py[DEBUG]: no need to setup swap
2021-11-17 17:59:22,905 - cc_mounts.py[DEBUG]: No modifications to fstab needed
2021-11-17 17:59:22,905 - handlers.py[DEBUG]: finish: init-network/config-mounts: SUCCESS: config-mounts ran successfully
2021-11-17 17:59:22,905 - stages.py[DEBUG]: Running module set_hostname (<module 'cloudinit.config.cc_set_hostname' from '/usr/lib/python3/dist-packages/cloudinit/config/cc_set_hostname.py'>) with frequency once-per-instance
2021-11-17 17:59:22,906 - handlers.py[DEBUG]: start: init-network/config-set_hostname: running config-set_hostname with frequency once-per-instance
2021-11-17 17:59:22,906 - util.py[DEBUG]: Writing to /var/lib/cloud/instances/test2/sem/config_set_hostname - wb: [644] 23 bytes
2021-11-17 17:59:22,906 - helpers.py[DEBUG]: Running config-set_hostname using lock (<FileLock using file '/var/lib/cloud/instances/test2/sem/config_set_hostname'>)
2021-11-17 17:59:22,906 - util.py[DEBUG]: Reading from /var/lib/cloud/data/set-hostname (quiet=False)
2021-11-17 17:59:22,906 - util.py[DEBUG]: Read 43 bytes from /var/lib/cloud/data/set-hostname
2021-11-17 17:59:22,907 - cc_set_hostname.py[DEBUG]: No hostname changes. Skipping set-hostname
2021-11-17 17:59:22,907 - handlers.py[DEBUG]: finish: init-network/config-set_hostname: SUCCESS: config-set_hostname ran successfully
2021-11-17 17:59:22,907 - stages.py[DEBUG]: Running module update_hostname (<module 'cloudinit.config.cc_update_hostname' from '/usr/lib/python3/dist-packages/cloudinit/config/cc_update_hostname.py'>) with frequency always
2021-11-17 17:59:22,907 - handlers.py[DEBUG]: start: init-network/config-update_hostname: running config-update_hostname with frequency always
2021-11-17 17:59:22,907 - helpers.py[DEBUG]: Running config-update_hostname using lock (<cloudinit.helpers.DummyLock object at 0x7fe21c4f33a0>)
2021-11-17 17:59:22,907 - cc_update_hostname.py[DEBUG]: Updating hostname to test2 (test2)
2021-11-17 17:59:22,907 - util.py[DEBUG]: Reading from /etc/hostname (quiet=False)
2021-11-17 17:59:22,907 - util.py[DEBUG]: Read 6 bytes from /etc/hostname
2021-11-17 17:59:22,907 - __init__.py[DEBUG]: Attempting to update hostname to test2 in 1 files
2021-11-17 17:59:22,907 - util.py[DEBUG]: Reading from /var/lib/cloud/data/previous-hostname (quiet=False)
2021-11-17 17:59:22,907 - util.py[DEBUG]: Writing to /var/lib/cloud/data/previous-hostname - wb: [644] 6 bytes
2021-11-17 17:59:22,908 - handlers.py[DEBUG]: finish: init-network/config-update_hostname: SUCCESS: config-update_hostname ran successfully
2021-11-17 17:59:22,908 - stages.py[DEBUG]: Running module update_etc_hosts (<module 'cloudinit.config.cc_update_etc_hosts' from '/usr/lib/python3/dist-packages/cloudinit/config/cc_update_etc_hosts.py'>) with frequency always
2021-11-17 17:59:22,908 - handlers.py[DEBUG]: start: init-network/config-update_etc_hosts: running config-update_etc_hosts with frequency always
2021-11-17 17:59:22,908 - helpers.py[DEBUG]: Running config-update_etc_hosts using lock (<cloudinit.helpers.DummyLock object at 0x7fe21c364f70>)
2021-11-17 17:59:22,909 - util.py[DEBUG]: Reading from /etc/cloud/templates/hosts.debian.tmpl (quiet=False)
2021-11-17 17:59:22,910 - util.py[DEBUG]: Read 901 bytes from /etc/cloud/templates/hosts.debian.tmpl
2021-11-17 17:59:22,910 - templater.py[DEBUG]: Rendering content of '/etc/cloud/templates/hosts.debian.tmpl' using renderer jinja
2021-11-17 17:59:22,913 - util.py[DEBUG]: Writing to /etc/hosts - wb: [644] 593 bytes
2021-11-17 17:59:22,914 - handlers.py[DEBUG]: finish: init-network/config-update_etc_hosts: SUCCESS: config-update_etc_hosts ran successfully
2021-11-17 17:59:22,914 - stages.py[DEBUG]: Running module ca-certs (<module 'cloudinit.config.cc_ca_certs' from '/usr/lib/python3/dist-packages/cloudinit/config/cc_ca_certs.py'>) with frequency once-per-instance
2021-11-17 17:59:22,914 - handlers.py[DEBUG]: start: init-network/config-ca-certs: running config-ca-certs with frequency once-per-instance
2021-11-17 17:59:22,914 - util.py[DEBUG]: Writing to /var/lib/cloud/instances/test2/sem/config_ca_certs - wb: [644] 24 bytes
2021-11-17 17:59:22,915 - helpers.py[DEBUG]: Running config-ca-certs using lock (<FileLock using file '/var/lib/cloud/instances/test2/sem/config_ca_certs'>)
2021-11-17 17:59:22,915 - cc_ca_certs.py[DEBUG]: Skipping module named ca-certs, no 'ca-certs' key in configuration
2021-11-17 17:59:22,915 - handlers.py[DEBUG]: finish: init-network/config-ca-certs: SUCCESS: config-ca-certs ran successfully
2021-11-17 17:59:22,915 - stages.py[DEBUG]: Running module rsyslog (<module 'cloudinit.config.cc_rsyslog' from '/usr/lib/python3/dist-packages/cloudinit/config/cc_rsyslog.py'>) with frequency once-per-instance
2021-11-17 17:59:22,915 - handlers.py[DEBUG]: start: init-network/config-rsyslog: running config-rsyslog with frequency once-per-instance
2021-11-17 17:59:22,915 - util.py[DEBUG]: Writing to /var/lib/cloud/instances/test2/sem/config_rsyslog - wb: [644] 24 bytes
2021-11-17 17:59:22,916 - helpers.py[DEBUG]: Running config-rsyslog using lock (<FileLock using file '/var/lib/cloud/instances/test2/sem/config_rsyslog'>)
2021-11-17 17:59:22,916 - cc_rsyslog.py[DEBUG]: Skipping module named rsyslog, no 'rsyslog' key in configuration
2021-11-17 17:59:22,916 - handlers.py[DEBUG]: finish: init-network/config-rsyslog: SUCCESS: config-rsyslog ran successfully
2021-11-17 17:59:22,916 - stages.py[DEBUG]: Running module users-groups (<module 'cloudinit.config.cc_users_groups' from '/usr/lib/python3/dist-packages/cloudinit/config/cc_users_groups.py'>) with frequency once-per-instance
2021-11-17 17:59:22,916 - handlers.py[DEBUG]: start: init-network/config-users-groups: running config-users-groups with frequency once-per-instance
2021-11-17 17:59:22,916 - util.py[DEBUG]: Writing to /var/lib/cloud/instances/test2/sem/config_users_groups - wb: [644] 24 bytes
2021-11-17 17:59:22,917 - helpers.py[DEBUG]: Running config-users-groups using lock (<FileLock using file '/var/lib/cloud/instances/test2/sem/config_users_groups'>)
2021-11-17 17:59:22,917 - util.py[DEBUG]: Reading from /etc/os-release (quiet=True)
2021-11-17 17:59:22,917 - util.py[DEBUG]: Read 382 bytes from /etc/os-release
2021-11-17 17:59:22,918 - util.py[DEBUG]: Reading from /etc/system-image/channel.ini (quiet=True)
2021-11-17 17:59:22,918 - util.py[DEBUG]: Read 0 bytes from /etc/system-image/channel.ini
2021-11-17 17:59:22,919 - subp.py[DEBUG]: Running command ['groupadd', 'ubuntu'] with allowed return codes [0] (shell=False, capture=True)
2021-11-17 17:59:22,943 - __init__.py[INFO]: Created new group ubuntu
2021-11-17 17:59:22,943 - subp.py[DEBUG]: Running command ['usermod', '-a', '-G', 'ubuntu', 'root'] with allowed return codes [0] (shell=False, capture=True)
2021-11-17 17:59:22,961 - __init__.py[INFO]: Added user 'root' to group 'ubuntu'
2021-11-17 17:59:22,962 - subp.py[DEBUG]: Running command ['usermod', '-a', '-G', 'ubuntu', 'sys'] with allowed return codes [0] (shell=False, capture=True)
2021-11-17 17:59:22,974 - __init__.py[INFO]: Added user 'sys' to group 'ubuntu'
2021-11-17 17:59:22,974 - util.py[DEBUG]: Reading from /etc/os-release (quiet=True)
2021-11-17 17:59:22,974 - util.py[DEBUG]: Read 382 bytes from /etc/os-release
2021-11-17 17:59:22,975 - util.py[DEBUG]: Reading from /etc/system-image/channel.ini (quiet=True)
2021-11-17 17:59:22,975 - util.py[DEBUG]: Read 0 bytes from /etc/system-image/channel.ini
2021-11-17 17:59:22,975 - __init__.py[WARNING]: Skipping creation of existing group 'users'
2021-11-17 17:59:22,977 - util.py[DEBUG]: Reading from /etc/os-release (quiet=True)
2021-11-17 17:59:22,977 - util.py[DEBUG]: Read 382 bytes from /etc/os-release
2021-11-17 17:59:22,978 - util.py[DEBUG]: Reading from /etc/system-image/channel.ini (quiet=True)
2021-11-17 17:59:22,978 - util.py[DEBUG]: Read 0 bytes from /etc/system-image/channel.ini
2021-11-17 17:59:22,978 - util.py[DEBUG]: Reading from /etc/os-release (quiet=True)
2021-11-17 17:59:22,978 - util.py[DEBUG]: Read 382 bytes from /etc/os-release
2021-11-17 17:59:22,979 - util.py[DEBUG]: Reading from /etc/system-image/channel.ini (quiet=True)
2021-11-17 17:59:22,979 - util.py[DEBUG]: Read 0 bytes from /etc/system-image/channel.ini
2021-11-17 17:59:22,979 - subp.py[DEBUG]: Running command ['groupadd', 'sam'] with allowed return codes [0] (shell=False, capture=True)
2021-11-17 17:59:22,992 - __init__.py[INFO]: Created new group sam
2021-11-17 17:59:22,992 - __init__.py[DEBUG]: created group 'sam' for user 'sam'
2021-11-17 17:59:22,992 - __init__.py[DEBUG]: Adding user sam
2021-11-17 17:59:22,992 - subp.py[DEBUG]: Running hidden command to protect sensitive input/output logstring: ['useradd', 'sam', '--groups', 'users', '--password', 'REDACTED', '--gid', 'sam', '-m']
2021-11-17 17:59:23,038 - subp.py[DEBUG]: Running hidden command to protect sensitive input/output logstring: chpasswd for sam
2021-11-17 17:59:23,070 - util.py[DEBUG]: Reading from /etc/sudoers (quiet=False)
2021-11-17 17:59:23,071 - util.py[DEBUG]: Read 755 bytes from /etc/sudoers
2021-11-17 17:59:23,072 - util.py[DEBUG]: Writing to /etc/sudoers.d/90-cloud-init-users - wb: [440] 145 bytes
2021-11-17 17:59:23,073 - util.py[DEBUG]: Reading from /etc/ssh/sshd_config (quiet=False)
2021-11-17 17:59:23,074 - util.py[DEBUG]: Read 3287 bytes from /etc/ssh/sshd_config
2021-11-17 17:59:23,091 - util.py[DEBUG]: Changing the ownership of /home/sam/.ssh to 1000:1001
2021-11-17 17:59:23,092 - util.py[DEBUG]: Writing to /home/sam/.ssh/authorized_keys - wb: [600] 0 bytes
2021-11-17 17:59:23,092 - util.py[DEBUG]: Changing the ownership of /home/sam/.ssh/authorized_keys to 1000:1001
2021-11-17 17:59:23,092 - util.py[DEBUG]: Reading from /home/sam/.ssh/authorized_keys (quiet=False)
2021-11-17 17:59:23,092 - util.py[DEBUG]: Read 0 bytes from /home/sam/.ssh/authorized_keys
2021-11-17 17:59:23,093 - util.py[DEBUG]: Writing to /home/sam/.ssh/authorized_keys - wb: [600] 586 bytes
2021-11-17 17:59:23,094 - util.py[DEBUG]: Reading from /etc/os-release (quiet=True)
2021-11-17 17:59:23,094 - util.py[DEBUG]: Read 382 bytes from /etc/os-release
2021-11-17 17:59:23,094 - util.py[DEBUG]: Reading from /etc/system-image/channel.ini (quiet=True)
2021-11-17 17:59:23,094 - util.py[DEBUG]: Read 0 bytes from /etc/system-image/channel.ini
2021-11-17 17:59:23,094 - __init__.py[DEBUG]: Adding user ubuntu
2021-11-17 17:59:23,095 - subp.py[DEBUG]: Running hidden command to protect sensitive input/output logstring: ['useradd', 'ubuntu', '--comment', 'Ubuntu', '--groups', 'adm,audio,cdrom,dialout,dip,floppy,lxd,netdev,plugdev,sudo,video', '--shell', '/bin/bash', '-m']
2021-11-17 17:59:23,099 - util.py[WARNING]: Failed to create user ubuntu
2021-11-17 17:59:23,100 - util.py[DEBUG]: Failed to create user ubuntu
Traceback (most recent call last):
  File "/usr/lib/python3/dist-packages/cloudinit/distros/__init__.py", line 527, in add_user
    subp.subp(useradd_cmd, logstring=log_useradd_cmd)
  File "/usr/lib/python3/dist-packages/cloudinit/subp.py", line 293, in subp
    raise ProcessExecutionError(stdout=out, stderr=err,
cloudinit.subp.ProcessExecutionError: Unexpected error while running command.
Command: ['useradd', 'ubuntu', '--comment', 'Ubuntu', '--groups', 'adm,audio,cdrom,dialout,dip,floppy,lxd,netdev,plugdev,sudo,video', '--shell', '/bin/bash', '-m']
Exit code: 9
Reason: -
Stdout: 
Stderr: useradd: group ubuntu exists - if you want to add this user to that group, use -g.
2021-11-17 17:59:23,103 - handlers.py[DEBUG]: finish: init-network/config-users-groups: FAIL: running config-users-groups with frequency once-per-instance
2021-11-17 17:59:23,104 - util.py[WARNING]: Running module users-groups (<module 'cloudinit.config.cc_users_groups' from '/usr/lib/python3/dist-packages/cloudinit/config/cc_users_groups.py'>) failed
2021-11-17 17:59:23,106 - util.py[DEBUG]: Running module users-groups (<module 'cloudinit.config.cc_users_groups' from '/usr/lib/python3/dist-packages/cloudinit/config/cc_users_groups.py'>) failed
Traceback (most recent call last):
  File "/usr/lib/python3/dist-packages/cloudinit/stages.py", line 965, in _run_modules
    ran, _r = cc.run(run_name, mod.handle, func_args,
  File "/usr/lib/python3/dist-packages/cloudinit/cloud.py", line 54, in run
    return self._runners.run(name, functor, args, freq, clear_on_fail)
  File "/usr/lib/python3/dist-packages/cloudinit/helpers.py", line 186, in run
    results = functor(*args)
  File "/usr/lib/python3/dist-packages/cloudinit/config/cc_users_groups.py", line 172, in handle
    cloud.distro.create_user(user, **config)
  File "/usr/lib/python3/dist-packages/cloudinit/distros/__init__.py", line 583, in create_user
    self.add_user(name, **kwargs)
  File "/usr/lib/python3/dist-packages/cloudinit/distros/__init__.py", line 530, in add_user
    raise e
  File "/usr/lib/python3/dist-packages/cloudinit/distros/__init__.py", line 527, in add_user
    subp.subp(useradd_cmd, logstring=log_useradd_cmd)
  File "/usr/lib/python3/dist-packages/cloudinit/subp.py", line 293, in subp
    raise ProcessExecutionError(stdout=out, stderr=err,
cloudinit.subp.ProcessExecutionError: Unexpected error while running command.
Command: ['useradd', 'ubuntu', '--comment', 'Ubuntu', '--groups', 'adm,audio,cdrom,dialout,dip,floppy,lxd,netdev,plugdev,sudo,video', '--shell', '/bin/bash', '-m']
Exit code: 9
Reason: -
Stdout: 
Stderr: useradd: group ubuntu exists - if you want to add this user to that group, use -g.
2021-11-17 17:59:23,110 - stages.py[DEBUG]: Running module ssh (<module 'cloudinit.config.cc_ssh' from '/usr/lib/python3/dist-packages/cloudinit/config/cc_ssh.py'>) with frequency once-per-instance
2021-11-17 17:59:23,110 - handlers.py[DEBUG]: start: init-network/config-ssh: running config-ssh with frequency once-per-instance
2021-11-17 17:59:23,111 - util.py[DEBUG]: Writing to /var/lib/cloud/instances/test2/sem/config_ssh - wb: [644] 24 bytes
2021-11-17 17:59:23,111 - helpers.py[DEBUG]: Running config-ssh using lock (<FileLock using file '/var/lib/cloud/instances/test2/sem/config_ssh'>)
2021-11-17 17:59:23,112 - subp.py[DEBUG]: Running command ['ssh-keygen', '-t', 'rsa', '-N', '', '-f', '/etc/ssh/ssh_host_rsa_key'] with allowed return codes [0] (shell=False, capture=True)
2021-11-17 17:59:23,338 - subp.py[DEBUG]: Running command ['ssh-keygen', '-t', 'dsa', '-N', '', '-f', '/etc/ssh/ssh_host_dsa_key'] with allowed return codes [0] (shell=False, capture=True)
2021-11-17 17:59:23,419 - subp.py[DEBUG]: Running command ['ssh-keygen', '-t', 'ecdsa', '-N', '', '-f', '/etc/ssh/ssh_host_ecdsa_key'] with allowed return codes [0] (shell=False, capture=True)
2021-11-17 17:59:23,427 - subp.py[DEBUG]: Running command ['ssh-keygen', '-t', 'ed25519', '-N', '', '-f', '/etc/ssh/ssh_host_ed25519_key'] with allowed return codes [0] (shell=False, capture=True)
2021-11-17 17:59:23,433 - util.py[DEBUG]: Reading from /etc/ssh/ssh_host_rsa_key.pub (quiet=False)
2021-11-17 17:59:23,434 - util.py[DEBUG]: Read 564 bytes from /etc/ssh/ssh_host_rsa_key.pub
2021-11-17 17:59:23,434 - util.py[DEBUG]: Reading from /etc/ssh/ssh_host_ecdsa_key.pub (quiet=False)
2021-11-17 17:59:23,434 - util.py[DEBUG]: Read 172 bytes from /etc/ssh/ssh_host_ecdsa_key.pub
2021-11-17 17:59:23,434 - util.py[DEBUG]: Reading from /etc/ssh/ssh_host_ed25519_key.pub (quiet=False)
2021-11-17 17:59:23,434 - util.py[DEBUG]: Read 92 bytes from /etc/ssh/ssh_host_ed25519_key.pub
2021-11-17 17:59:23,435 - util.py[WARNING]: Applying SSH credentials failed!
2021-11-17 17:59:23,437 - util.py[DEBUG]: Applying SSH credentials failed!
Traceback (most recent call last):
  File "/usr/lib/python3/dist-packages/cloudinit/config/cc_ssh.py", line 287, in handle
    apply_credentials(keys, user, disable_root, disable_root_opts)
  File "/usr/lib/python3/dist-packages/cloudinit/config/cc_ssh.py", line 296, in apply_credentials
    ssh_util.setup_user_keys(keys, user)
  File "/usr/lib/python3/dist-packages/cloudinit/ssh_util.py", line 437, in setup_user_keys
    (auth_key_fn, auth_key_entries) = extract_authorized_keys(username)
  File "/usr/lib/python3/dist-packages/cloudinit/ssh_util.py", line 385, in extract_authorized_keys
    (ssh_dir, pw_ent) = users_ssh_info(username)
  File "/usr/lib/python3/dist-packages/cloudinit/ssh_util.py", line 226, in users_ssh_info
    pw_ent = pwd.getpwnam(username)
KeyError: "getpwnam(): name not found: 'ubuntu'"
2021-11-17 17:59:23,442 - handlers.py[DEBUG]: finish: init-network/config-ssh: SUCCESS: config-ssh ran successfully
2021-11-17 17:59:23,442 - main.py[DEBUG]: Ran 15 modules with 1 failures
2021-11-17 17:59:23,443 - atomic_helper.py[DEBUG]: Atomically writing to file /var/lib/cloud/data/status.json (via temporary file /var/lib/cloud/data/tmp1j9k5im6) - w: [644] 936 bytes/chars
2021-11-17 17:59:23,443 - util.py[DEBUG]: Reading from /proc/uptime (quiet=False)
2021-11-17 17:59:23,443 - util.py[DEBUG]: Read 11 bytes from /proc/uptime
2021-11-17 17:59:23,443 - util.py[DEBUG]: cloud-init mode 'init' took 1.416 seconds (1.41)
2021-11-17 17:59:23,443 - handlers.py[DEBUG]: finish: init-network: FAIL: searching for network datasources
2021-11-17 17:59:31,501 - util.py[DEBUG]: Cloud-init v. 21.3-1-g6803368d-0ubuntu1~20.04.4 running 'modules:config' at Wed, 17 Nov 2021 17:59:31 +0000. Up 22.15 seconds.
2021-11-17 17:59:31,529 - stages.py[DEBUG]: Using distro class <class 'cloudinit.distros.ubuntu.Distro'>
2021-11-17 17:59:31,531 - stages.py[DEBUG]: Running module emit_upstart (<module 'cloudinit.config.cc_emit_upstart' from '/usr/lib/python3/dist-packages/cloudinit/config/cc_emit_upstart.py'>) with frequency always
2021-11-17 17:59:31,531 - handlers.py[DEBUG]: start: modules-config/config-emit_upstart: running config-emit_upstart with frequency always
2021-11-17 17:59:31,531 - helpers.py[DEBUG]: Running config-emit_upstart using lock (<cloudinit.helpers.DummyLock object at 0x7faaf9c1f340>)
2021-11-17 17:59:31,531 - cc_emit_upstart.py[DEBUG]: no /sbin/initctl located
2021-11-17 17:59:31,531 - cc_emit_upstart.py[DEBUG]: not upstart system, 'emit_upstart' disabled
2021-11-17 17:59:31,532 - handlers.py[DEBUG]: finish: modules-config/config-emit_upstart: SUCCESS: config-emit_upstart ran successfully
2021-11-17 17:59:31,532 - stages.py[DEBUG]: Running module snap (<module 'cloudinit.config.cc_snap' from '/usr/lib/python3/dist-packages/cloudinit/config/cc_snap.py'>) with frequency once-per-instance
2021-11-17 17:59:31,532 - handlers.py[DEBUG]: start: modules-config/config-snap: running config-snap with frequency once-per-instance
2021-11-17 17:59:31,532 - util.py[DEBUG]: Writing to /var/lib/cloud/instances/test2/sem/config_snap - wb: [644] 25 bytes
2021-11-17 17:59:31,532 - helpers.py[DEBUG]: Running config-snap using lock (<FileLock using file '/var/lib/cloud/instances/test2/sem/config_snap'>)
2021-11-17 17:59:31,532 - cc_snap.py[DEBUG]: Skipping module named snap, no 'snap' key in configuration
2021-11-17 17:59:31,533 - handlers.py[DEBUG]: finish: modules-config/config-snap: SUCCESS: config-snap ran successfully
2021-11-17 17:59:31,533 - stages.py[DEBUG]: Running module ssh-import-id (<module 'cloudinit.config.cc_ssh_import_id' from '/usr/lib/python3/dist-packages/cloudinit/config/cc_ssh_import_id.py'>) with frequency once-per-instance
2021-11-17 17:59:31,533 - handlers.py[DEBUG]: start: modules-config/config-ssh-import-id: running config-ssh-import-id with frequency once-per-instance
2021-11-17 17:59:31,533 - util.py[DEBUG]: Writing to /var/lib/cloud/instances/test2/sem/config_ssh_import_id - wb: [644] 25 bytes
2021-11-17 17:59:31,533 - helpers.py[DEBUG]: Running config-ssh-import-id using lock (<FileLock using file '/var/lib/cloud/instances/test2/sem/config_ssh_import_id'>)
2021-11-17 17:59:31,534 - cc_ssh_import_id.py[DEBUG]: User sam is not configured for ssh_import_id
2021-11-17 17:59:31,534 - handlers.py[DEBUG]: finish: modules-config/config-ssh-import-id: SUCCESS: config-ssh-import-id ran successfully
2021-11-17 17:59:31,534 - stages.py[DEBUG]: Running module locale (<module 'cloudinit.config.cc_locale' from '/usr/lib/python3/dist-packages/cloudinit/config/cc_locale.py'>) with frequency once-per-instance
2021-11-17 17:59:31,534 - handlers.py[DEBUG]: start: modules-config/config-locale: running config-locale with frequency once-per-instance
2021-11-17 17:59:31,534 - util.py[DEBUG]: Writing to /var/lib/cloud/instances/test2/sem/config_locale - wb: [644] 24 bytes
2021-11-17 17:59:31,535 - helpers.py[DEBUG]: Running config-locale using lock (<FileLock using file '/var/lib/cloud/instances/test2/sem/config_locale'>)
2021-11-17 17:59:31,535 - util.py[DEBUG]: Reading from /etc/default/locale (quiet=False)
2021-11-17 17:59:31,535 - util.py[DEBUG]: Read 13 bytes from /etc/default/locale
2021-11-17 17:59:31,565 - cc_locale.py[DEBUG]: Setting locale to C.UTF-8
2021-11-17 17:59:31,565 - debian.py[DEBUG]: System has 'LANG=C.UTF-8' requested 'C.UTF-8', skipping regeneration.
2021-11-17 17:59:31,565 - handlers.py[DEBUG]: finish: modules-config/config-locale: SUCCESS: config-locale ran successfully
2021-11-17 17:59:31,565 - stages.py[DEBUG]: Running module set-passwords (<module 'cloudinit.config.cc_set_passwords' from '/usr/lib/python3/dist-packages/cloudinit/config/cc_set_passwords.py'>) with frequency once-per-instance
2021-11-17 17:59:31,565 - handlers.py[DEBUG]: start: modules-config/config-set-passwords: running config-set-passwords with frequency once-per-instance
2021-11-17 17:59:31,566 - util.py[DEBUG]: Writing to /var/lib/cloud/instances/test2/sem/config_set_passwords - wb: [644] 25 bytes
2021-11-17 17:59:31,566 - helpers.py[DEBUG]: Running config-set-passwords using lock (<FileLock using file '/var/lib/cloud/instances/test2/sem/config_set_passwords'>)
2021-11-17 17:59:31,566 - cc_set_passwords.py[DEBUG]: Leaving SSH config 'PasswordAuthentication' unchanged. ssh_pwauth=None
2021-11-17 17:59:31,566 - handlers.py[DEBUG]: finish: modules-config/config-set-passwords: SUCCESS: config-set-passwords ran successfully
2021-11-17 17:59:31,566 - stages.py[DEBUG]: Running module grub-dpkg (<module 'cloudinit.config.cc_grub_dpkg' from '/usr/lib/python3/dist-packages/cloudinit/config/cc_grub_dpkg.py'>) with frequency once-per-instance
2021-11-17 17:59:31,567 - handlers.py[DEBUG]: start: modules-config/config-grub-dpkg: running config-grub-dpkg with frequency once-per-instance
2021-11-17 17:59:31,567 - util.py[DEBUG]: Writing to /var/lib/cloud/instances/test2/sem/config_grub_dpkg - wb: [644] 25 bytes
2021-11-17 17:59:31,567 - helpers.py[DEBUG]: Running config-grub-dpkg using lock (<FileLock using file '/var/lib/cloud/instances/test2/sem/config_grub_dpkg'>)
2021-11-17 17:59:31,567 - subp.py[DEBUG]: Running command ['grub-probe', '-t', 'disk', '/boot'] with allowed return codes [0] (shell=False, capture=True)
2021-11-17 17:59:31,581 - subp.py[DEBUG]: Running command ['udevadm', 'info', '--root', '--query=symlink', '/dev/vda'] with allowed return codes [0] (shell=False, capture=True)
2021-11-17 17:59:31,585 - cc_grub_dpkg.py[DEBUG]: considering these device symlinks: /dev/disk/by-id/virtio-BHYVE-8CC5-F63C-702D,/dev/disk/by-path/virtio-pci-0000:00:01.0,/dev/disk/by-path/pci-0000:00:01.0
2021-11-17 17:59:31,585 - cc_grub_dpkg.py[DEBUG]: filtered to these disk/by-id symlinks: /dev/disk/by-id/virtio-BHYVE-8CC5-F63C-702D
2021-11-17 17:59:31,585 - cc_grub_dpkg.py[DEBUG]: selected /dev/disk/by-id/virtio-BHYVE-8CC5-F63C-702D
2021-11-17 17:59:31,586 - cc_grub_dpkg.py[DEBUG]: Setting grub debconf-set-selections with '/dev/disk/by-id/virtio-BHYVE-8CC5-F63C-702D','false'
2021-11-17 17:59:31,586 - subp.py[DEBUG]: Running command ['debconf-set-selections'] with allowed return codes [0] (shell=False, capture=True)
2021-11-17 17:59:31,959 - handlers.py[DEBUG]: finish: modules-config/config-grub-dpkg: SUCCESS: config-grub-dpkg ran successfully
2021-11-17 17:59:31,959 - stages.py[DEBUG]: Running module apt-pipelining (<module 'cloudinit.config.cc_apt_pipelining' from '/usr/lib/python3/dist-packages/cloudinit/config/cc_apt_pipelining.py'>) with frequency once-per-instance
2021-11-17 17:59:31,960 - handlers.py[DEBUG]: start: modules-config/config-apt-pipelining: running config-apt-pipelining with frequency once-per-instance
2021-11-17 17:59:31,960 - util.py[DEBUG]: Writing to /var/lib/cloud/instances/test2/sem/config_apt_pipelining - wb: [644] 25 bytes
2021-11-17 17:59:31,960 - helpers.py[DEBUG]: Running config-apt-pipelining using lock (<FileLock using file '/var/lib/cloud/instances/test2/sem/config_apt_pipelining'>)
2021-11-17 17:59:31,961 - handlers.py[DEBUG]: finish: modules-config/config-apt-pipelining: SUCCESS: config-apt-pipelining ran successfully
2021-11-17 17:59:31,961 - stages.py[DEBUG]: Running module apt-configure (<module 'cloudinit.config.cc_apt_configure' from '/usr/lib/python3/dist-packages/cloudinit/config/cc_apt_configure.py'>) with frequency once-per-instance
2021-11-17 17:59:31,961 - handlers.py[DEBUG]: start: modules-config/config-apt-configure: running config-apt-configure with frequency once-per-instance
2021-11-17 17:59:31,961 - util.py[DEBUG]: Writing to /var/lib/cloud/instances/test2/sem/config_apt_configure - wb: [644] 25 bytes
2021-11-17 17:59:31,961 - helpers.py[DEBUG]: Running config-apt-configure using lock (<FileLock using file '/var/lib/cloud/instances/test2/sem/config_apt_configure'>)
2021-11-17 17:59:31,962 - cc_apt_configure.py[DEBUG]: debconf_selections was not set in config
2021-11-17 17:59:31,962 - util.py[DEBUG]: Reading from /etc/os-release (quiet=True)
2021-11-17 17:59:31,962 - util.py[DEBUG]: Read 382 bytes from /etc/os-release
2021-11-17 17:59:31,963 - util.py[DEBUG]: Reading from /etc/system-image/channel.ini (quiet=True)
2021-11-17 17:59:31,963 - util.py[DEBUG]: Read 0 bytes from /etc/system-image/channel.ini
2021-11-17 17:59:31,963 - cc_apt_configure.py[DEBUG]: handling apt config: {}
2021-11-17 17:59:31,963 - subp.py[DEBUG]: Running command ['lsb_release', '--all'] with allowed return codes [0] (shell=False, capture=True)
2021-11-17 17:59:32,024 - subp.py[DEBUG]: Running command ['dpkg', '--print-architecture'] with allowed return codes [0] (shell=False, capture=True)
2021-11-17 17:59:32,027 - cc_apt_configure.py[DEBUG]: got primary mirror: None
2021-11-17 17:59:32,028 - cc_apt_configure.py[DEBUG]: got security mirror: None
2021-11-17 17:59:32,028 - subp.py[DEBUG]: Running command ['dpkg', '--print-architecture'] with allowed return codes [0] (shell=False, capture=True)
2021-11-17 17:59:32,032 - util.py[DEBUG]: search for mirror in candidates: '[]'
2021-11-17 17:59:32,032 - util.py[DEBUG]: search for mirror in candidates: '[]'
2021-11-17 17:59:32,032 - __init__.py[DEBUG]: filtered distro mirror info: {'primary': 'http://archive.ubuntu.com/ubuntu', 'security': 'http://security.ubuntu.com/ubuntu'}
2021-11-17 17:59:32,032 - cc_apt_configure.py[DEBUG]: Apt Mirror info: {'primary': 'http://archive.ubuntu.com/ubuntu', 'security': 'http://security.ubuntu.com/ubuntu', 'PRIMARY': 'http://archive.ubuntu.com/ubuntu', 'SECURITY': 'http://security.ubuntu.com/ubuntu', 'MIRROR': 'http://archive.ubuntu.com/ubuntu'}
2021-11-17 17:59:32,032 - cc_apt_configure.py[INFO]: No custom template provided, fall back to builtin
2021-11-17 17:59:32,032 - util.py[DEBUG]: Reading from /etc/cloud/templates/sources.list.ubuntu.tmpl (quiet=False)
2021-11-17 17:59:32,033 - util.py[DEBUG]: Read 2858 bytes from /etc/cloud/templates/sources.list.ubuntu.tmpl
2021-11-17 17:59:32,042 - util.py[DEBUG]: Writing to /etc/apt/sources.list - wb: [644] 3120 bytes
2021-11-17 17:59:32,043 - handlers.py[DEBUG]: finish: modules-config/config-apt-configure: SUCCESS: config-apt-configure ran successfully
2021-11-17 17:59:32,043 - stages.py[DEBUG]: Running module ubuntu-advantage (<module 'cloudinit.config.cc_ubuntu_advantage' from '/usr/lib/python3/dist-packages/cloudinit/config/cc_ubuntu_advantage.py'>) with frequency once-per-instance
2021-11-17 17:59:32,043 - handlers.py[DEBUG]: start: modules-config/config-ubuntu-advantage: running config-ubuntu-advantage with frequency once-per-instance
2021-11-17 17:59:32,043 - util.py[DEBUG]: Writing to /var/lib/cloud/instances/test2/sem/config_ubuntu_advantage - wb: [644] 25 bytes
2021-11-17 17:59:32,044 - helpers.py[DEBUG]: Running config-ubuntu-advantage using lock (<FileLock using file '/var/lib/cloud/instances/test2/sem/config_ubuntu_advantage'>)
2021-11-17 17:59:32,044 - cc_ubuntu_advantage.py[DEBUG]: Skipping module named ubuntu-advantage, no 'ubuntu_advantage' configuration found
2021-11-17 17:59:32,044 - handlers.py[DEBUG]: finish: modules-config/config-ubuntu-advantage: SUCCESS: config-ubuntu-advantage ran successfully
2021-11-17 17:59:32,044 - stages.py[DEBUG]: Running module ntp (<module 'cloudinit.config.cc_ntp' from '/usr/lib/python3/dist-packages/cloudinit/config/cc_ntp.py'>) with frequency once-per-instance
2021-11-17 17:59:32,044 - handlers.py[DEBUG]: start: modules-config/config-ntp: running config-ntp with frequency once-per-instance
2021-11-17 17:59:32,045 - util.py[DEBUG]: Writing to /var/lib/cloud/instances/test2/sem/config_ntp - wb: [644] 25 bytes
2021-11-17 17:59:32,045 - helpers.py[DEBUG]: Running config-ntp using lock (<FileLock using file '/var/lib/cloud/instances/test2/sem/config_ntp'>)
2021-11-17 17:59:32,045 - cc_ntp.py[DEBUG]: Skipping module named ntp, not present or disabled by cfg
2021-11-17 17:59:32,045 - handlers.py[DEBUG]: finish: modules-config/config-ntp: SUCCESS: config-ntp ran successfully
2021-11-17 17:59:32,045 - stages.py[DEBUG]: Running module timezone (<module 'cloudinit.config.cc_timezone' from '/usr/lib/python3/dist-packages/cloudinit/config/cc_timezone.py'>) with frequency once-per-instance
2021-11-17 17:59:32,045 - handlers.py[DEBUG]: start: modules-config/config-timezone: running config-timezone with frequency once-per-instance
2021-11-17 17:59:32,046 - util.py[DEBUG]: Writing to /var/lib/cloud/instances/test2/sem/config_timezone - wb: [644] 24 bytes
2021-11-17 17:59:32,046 - helpers.py[DEBUG]: Running config-timezone using lock (<FileLock using file '/var/lib/cloud/instances/test2/sem/config_timezone'>)
2021-11-17 17:59:32,047 - util.py[DEBUG]: Writing to /etc/timezone - wb: [644] 13 bytes
2021-11-17 17:59:32,047 - util.py[DEBUG]: Attempting to remove /etc/localtime
2021-11-17 17:59:32,060 - handlers.py[DEBUG]: finish: modules-config/config-timezone: SUCCESS: config-timezone ran successfully
2021-11-17 17:59:32,060 - stages.py[DEBUG]: Running module disable-ec2-metadata (<module 'cloudinit.config.cc_disable_ec2_metadata' from '/usr/lib/python3/dist-packages/cloudinit/config/cc_disable_ec2_metadata.py'>) with frequency always
2021-11-17 17:59:32,060 - handlers.py[DEBUG]: start: modules-config/config-disable-ec2-metadata: running config-disable-ec2-metadata with frequency always
2021-11-17 17:59:32,061 - helpers.py[DEBUG]: Running config-disable-ec2-metadata using lock (<cloudinit.helpers.DummyLock object at 0x7faaf9c62610>)
2021-11-17 17:59:32,061 - cc_disable_ec2_metadata.py[DEBUG]: Skipping module named disable-ec2-metadata, disabling the ec2 route not enabled
2021-11-17 17:59:32,061 - handlers.py[DEBUG]: finish: modules-config/config-disable-ec2-metadata: SUCCESS: config-disable-ec2-metadata ran successfully
2021-11-17 17:59:32,061 - stages.py[DEBUG]: Running module runcmd (<module 'cloudinit.config.cc_runcmd' from '/usr/lib/python3/dist-packages/cloudinit/config/cc_runcmd.py'>) with frequency once-per-instance
2021-11-17 17:59:32,061 - handlers.py[DEBUG]: start: modules-config/config-runcmd: running config-runcmd with frequency once-per-instance
2021-11-17 17:59:32,061 - util.py[DEBUG]: Writing to /var/lib/cloud/instances/test2/sem/config_runcmd - wb: [644] 25 bytes
2021-11-17 17:59:32,062 - helpers.py[DEBUG]: Running config-runcmd using lock (<FileLock using file '/var/lib/cloud/instances/test2/sem/config_runcmd'>)
2021-11-17 17:59:32,062 - cc_runcmd.py[DEBUG]: Skipping module named runcmd, no 'runcmd' key in configuration
2021-11-17 17:59:32,062 - handlers.py[DEBUG]: finish: modules-config/config-runcmd: SUCCESS: config-runcmd ran successfully
2021-11-17 17:59:32,062 - stages.py[DEBUG]: Running module byobu (<module 'cloudinit.config.cc_byobu' from '/usr/lib/python3/dist-packages/cloudinit/config/cc_byobu.py'>) with frequency once-per-instance
2021-11-17 17:59:32,062 - handlers.py[DEBUG]: start: modules-config/config-byobu: running config-byobu with frequency once-per-instance
2021-11-17 17:59:32,062 - util.py[DEBUG]: Writing to /var/lib/cloud/instances/test2/sem/config_byobu - wb: [644] 24 bytes
2021-11-17 17:59:32,063 - helpers.py[DEBUG]: Running config-byobu using lock (<FileLock using file '/var/lib/cloud/instances/test2/sem/config_byobu'>)
2021-11-17 17:59:32,063 - cc_byobu.py[DEBUG]: Skipping module named byobu, no 'byobu' values found
2021-11-17 17:59:32,063 - handlers.py[DEBUG]: finish: modules-config/config-byobu: SUCCESS: config-byobu ran successfully
2021-11-17 17:59:32,063 - main.py[DEBUG]: Ran 14 modules with 0 failures
2021-11-17 17:59:32,063 - atomic_helper.py[DEBUG]: Atomically writing to file /var/lib/cloud/data/status.json (via temporary file /var/lib/cloud/data/tmpx91fsdv1) - w: [644] 964 bytes/chars
2021-11-17 17:59:32,063 - util.py[DEBUG]: Reading from /proc/uptime (quiet=False)
2021-11-17 17:59:32,064 - util.py[DEBUG]: Read 11 bytes from /proc/uptime
2021-11-17 17:59:32,064 - util.py[DEBUG]: cloud-init mode 'modules' took 0.709 seconds (0.70)
2021-11-17 17:59:32,064 - handlers.py[DEBUG]: finish: modules-config: SUCCESS: running modules for config
2021-11-17 17:59:32,981 - util.py[DEBUG]: Cloud-init v. 21.3-1-g6803368d-0ubuntu1~20.04.4 running 'modules:final' at Wed, 17 Nov 2021 17:59:32 +0000. Up 23.66 seconds.
2021-11-17 17:59:33,013 - stages.py[DEBUG]: Using distro class <class 'cloudinit.distros.ubuntu.Distro'>
2021-11-17 17:59:33,015 - stages.py[DEBUG]: Running module package-update-upgrade-install (<module 'cloudinit.config.cc_package_update_upgrade_install' from '/usr/lib/python3/dist-packages/cloudinit/config/cc_package_update_upgrade_install.py'>) with frequency once-per-instance
2021-11-17 17:59:33,015 - handlers.py[DEBUG]: start: modules-final/config-package-update-upgrade-install: running config-package-update-upgrade-install with frequency once-per-instance
2021-11-17 17:59:33,016 - util.py[DEBUG]: Writing to /var/lib/cloud/instances/test2/sem/config_package_update_upgrade_install - wb: [644] 25 bytes
2021-11-17 17:59:33,017 - helpers.py[DEBUG]: Running config-package-update-upgrade-install using lock (<FileLock using file '/var/lib/cloud/instances/test2/sem/config_package_update_upgrade_install'>)
2021-11-17 17:59:33,017 - util.py[DEBUG]: Writing to /var/lib/cloud/instances/test2/sem/update_sources - wb: [644] 24 bytes
2021-11-17 17:59:33,018 - helpers.py[DEBUG]: Running update-sources using lock (<FileLock using file '/var/lib/cloud/instances/test2/sem/update_sources'>)
2021-11-17 17:59:33,018 - subp.py[DEBUG]: Running command ['eatmydata', 'apt-get', '--option=Dpkg::Options::=--force-confold', '--option=Dpkg::options::=--force-unsafe-io', '--assume-yes', '--quiet', 'update'] with allowed return codes [0] (shell=False, capture=False)
2021-11-17 17:59:45,466 - util.py[DEBUG]: apt-update [eatmydata apt-get --option=Dpkg::Options::=--force-confold --option=Dpkg::options::=--force-unsafe-io --assume-yes --quiet update] took 12.448 seconds
2021-11-17 17:59:45,467 - subp.py[DEBUG]: Running command ['eatmydata', 'apt-get', '--option=Dpkg::Options::=--force-confold', '--option=Dpkg::options::=--force-unsafe-io', '--assume-yes', '--quiet', 'dist-upgrade'] with allowed return codes [0] (shell=False, capture=False)
2021-11-17 18:00:06,880 - util.py[DEBUG]: apt-upgrade [eatmydata apt-get --option=Dpkg::Options::=--force-confold --option=Dpkg::options::=--force-unsafe-io --assume-yes --quiet dist-upgrade] took 21.413 seconds
2021-11-17 18:00:06,882 - helpers.py[DEBUG]: update-sources already ran (freq=once-per-instance)
2021-11-17 18:00:06,882 - subp.py[DEBUG]: Running command ['eatmydata', 'apt-get', '--option=Dpkg::Options::=--force-confold', '--option=Dpkg::options::=--force-unsafe-io', '--assume-yes', '--quiet', 'install', 'git', 'ansible', 'tree', 'vim', 'nano', 'whois'] with allowed return codes [0] (shell=False, capture=False)
2021-11-17 18:00:29,963 - util.py[DEBUG]: apt-install [eatmydata apt-get --option=Dpkg::Options::=--force-confold --option=Dpkg::options::=--force-unsafe-io --assume-yes --quiet install git ansible tree vim nano whois] took 23.080 seconds
2021-11-17 18:00:29,965 - handlers.py[DEBUG]: finish: modules-final/config-package-update-upgrade-install: SUCCESS: config-package-update-upgrade-install ran successfully
2021-11-17 18:00:29,965 - stages.py[DEBUG]: Running module fan (<module 'cloudinit.config.cc_fan' from '/usr/lib/python3/dist-packages/cloudinit/config/cc_fan.py'>) with frequency once-per-instance
2021-11-17 18:00:29,965 - handlers.py[DEBUG]: start: modules-final/config-fan: running config-fan with frequency once-per-instance
2021-11-17 18:00:29,966 - util.py[DEBUG]: Writing to /var/lib/cloud/instances/test2/sem/config_fan - wb: [644] 25 bytes
2021-11-17 18:00:29,971 - helpers.py[DEBUG]: Running config-fan using lock (<FileLock using file '/var/lib/cloud/instances/test2/sem/config_fan'>)
2021-11-17 18:00:29,971 - cc_fan.py[DEBUG]: fan: no 'fan' config entry. disabling
2021-11-17 18:00:29,972 - handlers.py[DEBUG]: finish: modules-final/config-fan: SUCCESS: config-fan ran successfully
2021-11-17 18:00:29,972 - stages.py[DEBUG]: Running module landscape (<module 'cloudinit.config.cc_landscape' from '/usr/lib/python3/dist-packages/cloudinit/config/cc_landscape.py'>) with frequency once-per-instance
2021-11-17 18:00:29,972 - handlers.py[DEBUG]: start: modules-final/config-landscape: running config-landscape with frequency once-per-instance
2021-11-17 18:00:29,972 - util.py[DEBUG]: Writing to /var/lib/cloud/instances/test2/sem/config_landscape - wb: [644] 25 bytes
2021-11-17 18:00:29,972 - helpers.py[DEBUG]: Running config-landscape using lock (<FileLock using file '/var/lib/cloud/instances/test2/sem/config_landscape'>)
2021-11-17 18:00:29,972 - handlers.py[DEBUG]: finish: modules-final/config-landscape: SUCCESS: config-landscape ran successfully
2021-11-17 18:00:29,972 - stages.py[DEBUG]: Running module lxd (<module 'cloudinit.config.cc_lxd' from '/usr/lib/python3/dist-packages/cloudinit/config/cc_lxd.py'>) with frequency once-per-instance
2021-11-17 18:00:29,972 - handlers.py[DEBUG]: start: modules-final/config-lxd: running config-lxd with frequency once-per-instance
2021-11-17 18:00:29,973 - util.py[DEBUG]: Writing to /var/lib/cloud/instances/test2/sem/config_lxd - wb: [644] 25 bytes
2021-11-17 18:00:29,973 - helpers.py[DEBUG]: Running config-lxd using lock (<FileLock using file '/var/lib/cloud/instances/test2/sem/config_lxd'>)
2021-11-17 18:00:29,973 - cc_lxd.py[DEBUG]: Skipping module named lxd, not present or disabled by cfg
2021-11-17 18:00:29,973 - handlers.py[DEBUG]: finish: modules-final/config-lxd: SUCCESS: config-lxd ran successfully
2021-11-17 18:00:29,973 - stages.py[DEBUG]: Running module ubuntu-drivers (<module 'cloudinit.config.cc_ubuntu_drivers' from '/usr/lib/python3/dist-packages/cloudinit/config/cc_ubuntu_drivers.py'>) with frequency once-per-instance
2021-11-17 18:00:29,973 - handlers.py[DEBUG]: start: modules-final/config-ubuntu-drivers: running config-ubuntu-drivers with frequency once-per-instance
2021-11-17 18:00:29,973 - util.py[DEBUG]: Writing to /var/lib/cloud/instances/test2/sem/config_ubuntu_drivers - wb: [644] 24 bytes
2021-11-17 18:00:29,973 - helpers.py[DEBUG]: Running config-ubuntu-drivers using lock (<FileLock using file '/var/lib/cloud/instances/test2/sem/config_ubuntu_drivers'>)
2021-11-17 18:00:29,973 - cc_ubuntu_drivers.py[DEBUG]: Skipping module named ubuntu-drivers, no 'drivers' key in config
2021-11-17 18:00:29,973 - handlers.py[DEBUG]: finish: modules-final/config-ubuntu-drivers: SUCCESS: config-ubuntu-drivers ran successfully
2021-11-17 18:00:29,974 - stages.py[DEBUG]: Running module puppet (<module 'cloudinit.config.cc_puppet' from '/usr/lib/python3/dist-packages/cloudinit/config/cc_puppet.py'>) with frequency once-per-instance
2021-11-17 18:00:29,974 - handlers.py[DEBUG]: start: modules-final/config-puppet: running config-puppet with frequency once-per-instance
2021-11-17 18:00:29,974 - util.py[DEBUG]: Writing to /var/lib/cloud/instances/test2/sem/config_puppet - wb: [644] 25 bytes
2021-11-17 18:00:29,974 - helpers.py[DEBUG]: Running config-puppet using lock (<FileLock using file '/var/lib/cloud/instances/test2/sem/config_puppet'>)
2021-11-17 18:00:29,974 - cc_puppet.py[DEBUG]: Skipping module named puppet, no 'puppet' configuration found
2021-11-17 18:00:29,974 - handlers.py[DEBUG]: finish: modules-final/config-puppet: SUCCESS: config-puppet ran successfully
2021-11-17 18:00:29,974 - stages.py[DEBUG]: Running module chef (<module 'cloudinit.config.cc_chef' from '/usr/lib/python3/dist-packages/cloudinit/config/cc_chef.py'>) with frequency always
2021-11-17 18:00:29,974 - handlers.py[DEBUG]: start: modules-final/config-chef: running config-chef with frequency always
2021-11-17 18:00:29,974 - helpers.py[DEBUG]: Running config-chef using lock (<cloudinit.helpers.DummyLock object at 0x7ff22870f1c0>)
2021-11-17 18:00:29,974 - cc_chef.py[DEBUG]: Skipping module named chef, no 'chef' key in configuration
2021-11-17 18:00:29,975 - handlers.py[DEBUG]: finish: modules-final/config-chef: SUCCESS: config-chef ran successfully
2021-11-17 18:00:29,975 - stages.py[DEBUG]: Running module mcollective (<module 'cloudinit.config.cc_mcollective' from '/usr/lib/python3/dist-packages/cloudinit/config/cc_mcollective.py'>) with frequency once-per-instance
2021-11-17 18:00:29,975 - handlers.py[DEBUG]: start: modules-final/config-mcollective: running config-mcollective with frequency once-per-instance
2021-11-17 18:00:29,975 - util.py[DEBUG]: Writing to /var/lib/cloud/instances/test2/sem/config_mcollective - wb: [644] 24 bytes
2021-11-17 18:00:29,975 - helpers.py[DEBUG]: Running config-mcollective using lock (<FileLock using file '/var/lib/cloud/instances/test2/sem/config_mcollective'>)
2021-11-17 18:00:29,975 - cc_mcollective.py[DEBUG]: Skipping module named mcollective, no 'mcollective' key in configuration
2021-11-17 18:00:29,975 - handlers.py[DEBUG]: finish: modules-final/config-mcollective: SUCCESS: config-mcollective ran successfully
2021-11-17 18:00:29,975 - stages.py[DEBUG]: Running module salt-minion (<module 'cloudinit.config.cc_salt_minion' from '/usr/lib/python3/dist-packages/cloudinit/config/cc_salt_minion.py'>) with frequency once-per-instance
2021-11-17 18:00:29,975 - handlers.py[DEBUG]: start: modules-final/config-salt-minion: running config-salt-minion with frequency once-per-instance
2021-11-17 18:00:29,976 - util.py[DEBUG]: Writing to /var/lib/cloud/instances/test2/sem/config_salt_minion - wb: [644] 25 bytes
2021-11-17 18:00:29,976 - helpers.py[DEBUG]: Running config-salt-minion using lock (<FileLock using file '/var/lib/cloud/instances/test2/sem/config_salt_minion'>)
2021-11-17 18:00:29,976 - cc_salt_minion.py[DEBUG]: Skipping module named salt-minion, no 'salt_minion' key in configuration
2021-11-17 18:00:29,976 - handlers.py[DEBUG]: finish: modules-final/config-salt-minion: SUCCESS: config-salt-minion ran successfully
2021-11-17 18:00:29,976 - stages.py[DEBUG]: Running module reset_rmc (<module 'cloudinit.config.cc_reset_rmc' from '/usr/lib/python3/dist-packages/cloudinit/config/cc_reset_rmc.py'>) with frequency once-per-instance
2021-11-17 18:00:29,976 - handlers.py[DEBUG]: start: modules-final/config-reset_rmc: running config-reset_rmc with frequency once-per-instance
2021-11-17 18:00:29,976 - util.py[DEBUG]: Writing to /var/lib/cloud/instances/test2/sem/config_reset_rmc - wb: [644] 25 bytes
2021-11-17 18:00:29,976 - helpers.py[DEBUG]: Running config-reset_rmc using lock (<FileLock using file '/var/lib/cloud/instances/test2/sem/config_reset_rmc'>)
2021-11-17 18:00:29,976 - cc_reset_rmc.py[DEBUG]: module disabled, RSCT_PATH not present
2021-11-17 18:00:29,976 - handlers.py[DEBUG]: finish: modules-final/config-reset_rmc: SUCCESS: config-reset_rmc ran successfully
2021-11-17 18:00:29,977 - stages.py[DEBUG]: Running module refresh_rmc_and_interface (<module 'cloudinit.config.cc_refresh_rmc_and_interface' from '/usr/lib/python3/dist-packages/cloudinit/config/cc_refresh_rmc_and_interface.py'>) with frequency always
2021-11-17 18:00:29,977 - handlers.py[DEBUG]: start: modules-final/config-refresh_rmc_and_interface: running config-refresh_rmc_and_interface with frequency always
2021-11-17 18:00:29,977 - helpers.py[DEBUG]: Running config-refresh_rmc_and_interface using lock (<cloudinit.helpers.DummyLock object at 0x7ff22870f1c0>)
2021-11-17 18:00:29,977 - cc_refresh_rmc_and_interface.py[DEBUG]: No 'rmcctrl' in path, disabled
2021-11-17 18:00:29,977 - handlers.py[DEBUG]: finish: modules-final/config-refresh_rmc_and_interface: SUCCESS: config-refresh_rmc_and_interface ran successfully
2021-11-17 18:00:29,977 - stages.py[DEBUG]: Running module rightscale_userdata (<module 'cloudinit.config.cc_rightscale_userdata' from '/usr/lib/python3/dist-packages/cloudinit/config/cc_rightscale_userdata.py'>) with frequency once-per-instance
2021-11-17 18:00:29,977 - handlers.py[DEBUG]: start: modules-final/config-rightscale_userdata: running config-rightscale_userdata with frequency once-per-instance
2021-11-17 18:00:29,978 - util.py[DEBUG]: Writing to /var/lib/cloud/instances/test2/sem/config_rightscale_userdata - wb: [644] 25 bytes
2021-11-17 18:00:29,978 - helpers.py[DEBUG]: Running config-rightscale_userdata using lock (<FileLock using file '/var/lib/cloud/instances/test2/sem/config_rightscale_userdata'>)
2021-11-17 18:00:29,978 - cc_rightscale_userdata.py[DEBUG]: Failed to get raw userdata in module rightscale_userdata
2021-11-17 18:00:29,978 - handlers.py[DEBUG]: finish: modules-final/config-rightscale_userdata: SUCCESS: config-rightscale_userdata ran successfully
2021-11-17 18:00:29,978 - stages.py[DEBUG]: Running module scripts-vendor (<module 'cloudinit.config.cc_scripts_vendor' from '/usr/lib/python3/dist-packages/cloudinit/config/cc_scripts_vendor.py'>) with frequency once-per-instance
2021-11-17 18:00:29,978 - handlers.py[DEBUG]: start: modules-final/config-scripts-vendor: running config-scripts-vendor with frequency once-per-instance
2021-11-17 18:00:29,978 - util.py[DEBUG]: Writing to /var/lib/cloud/instances/test2/sem/config_scripts_vendor - wb: [644] 25 bytes
2021-11-17 18:00:29,978 - helpers.py[DEBUG]: Running config-scripts-vendor using lock (<FileLock using file '/var/lib/cloud/instances/test2/sem/config_scripts_vendor'>)
2021-11-17 18:00:29,979 - handlers.py[DEBUG]: finish: modules-final/config-scripts-vendor: SUCCESS: config-scripts-vendor ran successfully
2021-11-17 18:00:29,979 - stages.py[DEBUG]: Running module scripts-per-once (<module 'cloudinit.config.cc_scripts_per_once' from '/usr/lib/python3/dist-packages/cloudinit/config/cc_scripts_per_once.py'>) with frequency once
2021-11-17 18:00:29,979 - handlers.py[DEBUG]: start: modules-final/config-scripts-per-once: running config-scripts-per-once with frequency once
2021-11-17 18:00:29,980 - util.py[DEBUG]: Writing to /var/lib/cloud/sem/config_scripts_per_once.once - wb: [644] 25 bytes
2021-11-17 18:00:29,980 - helpers.py[DEBUG]: Running config-scripts-per-once using lock (<FileLock using file '/var/lib/cloud/sem/config_scripts_per_once.once'>)
2021-11-17 18:00:29,981 - handlers.py[DEBUG]: finish: modules-final/config-scripts-per-once: SUCCESS: config-scripts-per-once ran successfully
2021-11-17 18:00:29,981 - stages.py[DEBUG]: Running module scripts-per-boot (<module 'cloudinit.config.cc_scripts_per_boot' from '/usr/lib/python3/dist-packages/cloudinit/config/cc_scripts_per_boot.py'>) with frequency always
2021-11-17 18:00:29,981 - handlers.py[DEBUG]: start: modules-final/config-scripts-per-boot: running config-scripts-per-boot with frequency always
2021-11-17 18:00:29,981 - helpers.py[DEBUG]: Running config-scripts-per-boot using lock (<cloudinit.helpers.DummyLock object at 0x7ff228706610>)
2021-11-17 18:00:29,982 - handlers.py[DEBUG]: finish: modules-final/config-scripts-per-boot: SUCCESS: config-scripts-per-boot ran successfully
2021-11-17 18:00:29,982 - stages.py[DEBUG]: Running module scripts-per-instance (<module 'cloudinit.config.cc_scripts_per_instance' from '/usr/lib/python3/dist-packages/cloudinit/config/cc_scripts_per_instance.py'>) with frequency once-per-instance
2021-11-17 18:00:29,982 - handlers.py[DEBUG]: start: modules-final/config-scripts-per-instance: running config-scripts-per-instance with frequency once-per-instance
2021-11-17 18:00:29,983 - util.py[DEBUG]: Writing to /var/lib/cloud/instances/test2/sem/config_scripts_per_instance - wb: [644] 25 bytes
2021-11-17 18:00:29,983 - helpers.py[DEBUG]: Running config-scripts-per-instance using lock (<FileLock using file '/var/lib/cloud/instances/test2/sem/config_scripts_per_instance'>)
2021-11-17 18:00:29,983 - handlers.py[DEBUG]: finish: modules-final/config-scripts-per-instance: SUCCESS: config-scripts-per-instance ran successfully
2021-11-17 18:00:29,984 - stages.py[DEBUG]: Running module scripts-user (<module 'cloudinit.config.cc_scripts_user' from '/usr/lib/python3/dist-packages/cloudinit/config/cc_scripts_user.py'>) with frequency once-per-instance
2021-11-17 18:00:29,984 - handlers.py[DEBUG]: start: modules-final/config-scripts-user: running config-scripts-user with frequency once-per-instance
2021-11-17 18:00:29,984 - util.py[DEBUG]: Writing to /var/lib/cloud/instances/test2/sem/config_scripts_user - wb: [644] 25 bytes
2021-11-17 18:00:29,984 - helpers.py[DEBUG]: Running config-scripts-user using lock (<FileLock using file '/var/lib/cloud/instances/test2/sem/config_scripts_user'>)
2021-11-17 18:00:29,984 - handlers.py[DEBUG]: finish: modules-final/config-scripts-user: SUCCESS: config-scripts-user ran successfully
2021-11-17 18:00:29,984 - stages.py[DEBUG]: Running module ssh-authkey-fingerprints (<module 'cloudinit.config.cc_ssh_authkey_fingerprints' from '/usr/lib/python3/dist-packages/cloudinit/config/cc_ssh_authkey_fingerprints.py'>) with frequency once-per-instance
2021-11-17 18:00:29,985 - handlers.py[DEBUG]: start: modules-final/config-ssh-authkey-fingerprints: running config-ssh-authkey-fingerprints with frequency once-per-instance
2021-11-17 18:00:29,985 - util.py[DEBUG]: Writing to /var/lib/cloud/instances/test2/sem/config_ssh_authkey_fingerprints - wb: [644] 25 bytes
2021-11-17 18:00:29,985 - helpers.py[DEBUG]: Running config-ssh-authkey-fingerprints using lock (<FileLock using file '/var/lib/cloud/instances/test2/sem/config_ssh_authkey_fingerprints'>)
2021-11-17 18:00:29,985 - util.py[DEBUG]: Reading from /etc/ssh/sshd_config (quiet=False)
2021-11-17 18:00:29,986 - util.py[DEBUG]: Read 3287 bytes from /etc/ssh/sshd_config
2021-11-17 18:00:29,987 - util.py[DEBUG]: Reading from /home/sam/.ssh/authorized_keys (quiet=False)
2021-11-17 18:00:29,988 - util.py[DEBUG]: Read 586 bytes from /home/sam/.ssh/authorized_keys
2021-11-17 18:00:30,005 - handlers.py[DEBUG]: finish: modules-final/config-ssh-authkey-fingerprints: FAIL: running config-ssh-authkey-fingerprints with frequency once-per-instance
2021-11-17 18:00:30,005 - util.py[WARNING]: Running module ssh-authkey-fingerprints (<module 'cloudinit.config.cc_ssh_authkey_fingerprints' from '/usr/lib/python3/dist-packages/cloudinit/config/cc_ssh_authkey_fingerprints.py'>) failed
2021-11-17 18:00:30,011 - util.py[DEBUG]: Running module ssh-authkey-fingerprints (<module 'cloudinit.config.cc_ssh_authkey_fingerprints' from '/usr/lib/python3/dist-packages/cloudinit/config/cc_ssh_authkey_fingerprints.py'>) failed
Traceback (most recent call last):
  File "/usr/lib/python3/dist-packages/cloudinit/stages.py", line 965, in _run_modules
    ran, _r = cc.run(run_name, mod.handle, func_args,
  File "/usr/lib/python3/dist-packages/cloudinit/cloud.py", line 54, in run
    return self._runners.run(name, functor, args, freq, clear_on_fail)
  File "/usr/lib/python3/dist-packages/cloudinit/helpers.py", line 186, in run
    results = functor(*args)
  File "/usr/lib/python3/dist-packages/cloudinit/config/cc_ssh_authkey_fingerprints.py", line 107, in handle
    (key_fn, key_entries) = ssh_util.extract_authorized_keys(user_name)
  File "/usr/lib/python3/dist-packages/cloudinit/ssh_util.py", line 385, in extract_authorized_keys
    (ssh_dir, pw_ent) = users_ssh_info(username)
  File "/usr/lib/python3/dist-packages/cloudinit/ssh_util.py", line 226, in users_ssh_info
    pw_ent = pwd.getpwnam(username)
KeyError: "getpwnam(): name not found: 'ubuntu'"
2021-11-17 18:00:30,017 - stages.py[DEBUG]: Running module keys-to-console (<module 'cloudinit.config.cc_keys_to_console' from '/usr/lib/python3/dist-packages/cloudinit/config/cc_keys_to_console.py'>) with frequency once-per-instance
2021-11-17 18:00:30,017 - handlers.py[DEBUG]: start: modules-final/config-keys-to-console: running config-keys-to-console with frequency once-per-instance
2021-11-17 18:00:30,018 - util.py[DEBUG]: Writing to /var/lib/cloud/instances/test2/sem/config_keys_to_console - wb: [644] 24 bytes
2021-11-17 18:00:30,018 - helpers.py[DEBUG]: Running config-keys-to-console using lock (<FileLock using file '/var/lib/cloud/instances/test2/sem/config_keys_to_console'>)
2021-11-17 18:00:30,018 - subp.py[DEBUG]: Running command ['/usr/lib/cloud-init/write-ssh-key-fingerprints', '', 'ssh-dss'] with allowed return codes [0] (shell=False, capture=True)
2021-11-17 18:00:30,079 - handlers.py[DEBUG]: finish: modules-final/config-keys-to-console: SUCCESS: config-keys-to-console ran successfully
2021-11-17 18:00:30,080 - stages.py[DEBUG]: Running module phone-home (<module 'cloudinit.config.cc_phone_home' from '/usr/lib/python3/dist-packages/cloudinit/config/cc_phone_home.py'>) with frequency once-per-instance
2021-11-17 18:00:30,080 - handlers.py[DEBUG]: start: modules-final/config-phone-home: running config-phone-home with frequency once-per-instance
2021-11-17 18:00:30,080 - util.py[DEBUG]: Writing to /var/lib/cloud/instances/test2/sem/config_phone_home - wb: [644] 24 bytes
2021-11-17 18:00:30,080 - helpers.py[DEBUG]: Running config-phone-home using lock (<FileLock using file '/var/lib/cloud/instances/test2/sem/config_phone_home'>)
2021-11-17 18:00:30,080 - cc_phone_home.py[DEBUG]: Skipping module named phone-home, no 'phone_home' configuration found
2021-11-17 18:00:30,081 - handlers.py[DEBUG]: finish: modules-final/config-phone-home: SUCCESS: config-phone-home ran successfully
2021-11-17 18:00:30,081 - stages.py[DEBUG]: Running module final-message (<module 'cloudinit.config.cc_final_message' from '/usr/lib/python3/dist-packages/cloudinit/config/cc_final_message.py'>) with frequency always
2021-11-17 18:00:30,081 - handlers.py[DEBUG]: start: modules-final/config-final-message: running config-final-message with frequency always
2021-11-17 18:00:30,081 - helpers.py[DEBUG]: Running config-final-message using lock (<cloudinit.helpers.DummyLock object at 0x7ff22858b0a0>)
2021-11-17 18:00:30,081 - util.py[DEBUG]: Reading from /proc/uptime (quiet=False)
2021-11-17 18:00:30,081 - util.py[DEBUG]: Read 11 bytes from /proc/uptime
2021-11-17 18:00:30,084 - util.py[DEBUG]: Cloud-init v. 21.3-1-g6803368d-0ubuntu1~20.04.4 finished at Wed, 17 Nov 2021 18:00:30 +0000. Datasource DataSourceNoCloud [seed=/dev/sr0][dsmode=net].  Up 80.86 seconds
2021-11-17 18:00:30,085 - util.py[DEBUG]: Writing to /var/lib/cloud/instance/boot-finished - wb: [644] 79 bytes
2021-11-17 18:00:30,085 - handlers.py[DEBUG]: finish: modules-final/config-final-message: SUCCESS: config-final-message ran successfully
2021-11-17 18:00:30,086 - stages.py[DEBUG]: Running module power-state-change (<module 'cloudinit.config.cc_power_state_change' from '/usr/lib/python3/dist-packages/cloudinit/config/cc_power_state_change.py'>) with frequency once-per-instance
2021-11-17 18:00:30,086 - handlers.py[DEBUG]: start: modules-final/config-power-state-change: running config-power-state-change with frequency once-per-instance
2021-11-17 18:00:30,086 - util.py[DEBUG]: Writing to /var/lib/cloud/instances/test2/sem/config_power_state_change - wb: [644] 24 bytes
2021-11-17 18:00:30,086 - helpers.py[DEBUG]: Running config-power-state-change using lock (<FileLock using file '/var/lib/cloud/instances/test2/sem/config_power_state_change'>)
2021-11-17 18:00:30,086 - cc_power_state_change.py[DEBUG]: no power_state provided. doing nothing
2021-11-17 18:00:30,086 - handlers.py[DEBUG]: finish: modules-final/config-power-state-change: SUCCESS: config-power-state-change ran successfully
2021-11-17 18:00:30,086 - main.py[DEBUG]: Ran 22 modules with 1 failures
2021-11-17 18:00:30,088 - atomic_helper.py[DEBUG]: Atomically writing to file /var/lib/cloud/data/status.json (via temporary file /var/lib/cloud/data/tmpupxb45uf) - w: [644] 1082 bytes/chars
2021-11-17 18:00:30,088 - atomic_helper.py[DEBUG]: Atomically writing to file /var/lib/cloud/data/result.json (via temporary file /var/lib/cloud/data/tmps8xw56b_) - w: [644] 573 bytes/chars
2021-11-17 18:00:30,089 - util.py[DEBUG]: Creating symbolic link from '/run/cloud-init/result.json' => '../../var/lib/cloud/data/result.json'
2021-11-17 18:00:30,089 - util.py[DEBUG]: Reading from /proc/uptime (quiet=False)
2021-11-17 18:00:30,089 - util.py[DEBUG]: Read 11 bytes from /proc/uptime
2021-11-17 18:00:30,089 - util.py[DEBUG]: cloud-init mode 'modules' took 57.213 seconds (57.21)
2021-11-17 18:00:30,089 - handlers.py[DEBUG]: finish: modules-final: FAIL: running modules for final